Workbook
Name _xlchart.v1.2: 'Graphique des resultats'!$C$25:$C$36
Name _xlchart.v1.3: 'Graphique des resultats'!$D$24
Name _xlchart.v1.0: 'Graphique des resultats'!$B$25:$B$36
Name _xlchart.v1.7: 'Graphique des resultats'!$F$24
Name _xlchart.v1.6: 'Graphique des resultats'!$E$25:$E$36
Name _xlchart.v1.5: 'Graphique des resultats'!$E$24
Name _xlchart.v1.4: 'Graphique des resultats'!$D$25:$D$36
Name _xlchart.v1.1: 'Graphique des resultats'!$C$24
Name _xlchart.v1.8: 'Graphique des resultats'!$F$25:$F$36

Sheet ECOLES INTERVENTION
A1: REPUBLIQUE DU NIGER
A2: FRATERNITÉ - TRAVAIL - PROGRÈS
A3: REGION DE MARADI
A4: DIRECTION REGIONALE DE L'EDUCATION NATIONALE,
A5: DE L'ALPHABETISATION ET DE LA PROMOTION DES LANGUES
A6: IEP DE TCHADOUA
A7: Colonne1 | B7: Colonne2 | C7: Colonne3 | D7: Colonne4 | E7: Colonne5 | F7: Colonne6 | G7: Colonne7 | H7: Colonne8 | I7: Colonne9 | J7: Colonne10 | K7: Colonne11 | L7: Colonne12 | M7: Colonne13
A8: ECOLE ZANGON NA RUWA
A9: N° | B9: Noms et prénoms | D9: Moyenne 1er semestre | F9: Moyenne 2 ème semestre | H9: 3ème semestre | J9: Moyenne Générale | L9: Situation finale | M9: Passe en CM2 | N9: Redouble | O9: Abandon | P9: Décès et transfère
A10: 1 | B10: Safia Tsahirou | D10: 5.25 | F10: 5.8 | H10: 6 | J10: =(('ECOLES INTERVENTION'!$D10+'ECOLES INTERVENTION'!$F10+'ECOLES INTERVENTION'!$H10)/3) -> 5.6833333 | L10: Passe | M10: 1
A11: 2 | B11: Charifa Maazou | D11: 2.75 | F11: 3 | H11: 3.15 | J11: =(('ECOLES INTERVENTION'!$D11+'ECOLES INTERVENTION'!$F11+'ECOLES INTERVENTION'!$H11)/3) -> 2.9666667 | L11: Redouble | N11: 1
A12: 3 | B12: Oumeira Hamissou | D12: 4.9 | F12: 5.15 | H12: 4.25 | J12: =(('ECOLES INTERVENTION'!$D12+'ECOLES INTERVENTION'!$F12+'ECOLES INTERVENTION'!$H12)/3) -> 4.7666667 | L12: Passe | M12: 1
A13: 4 | B13: Majida Harouna | D13: 3.99 | F13: 4.45 | H13: 4.95 | J13: =(('ECOLES INTERVENTION'!$D13+'ECOLES INTERVENTION'!$F13+'ECOLES INTERVENTION'!$H13)/3) -> 4.4633333 | L13: Passe | M13: 1
A14: 5 | B14: Manira Ali | D14: 4 | F14: 5.25 | H14: 5.95 | J14: =(('ECOLES INTERVENTION'!$D14+'ECOLES INTERVENTION'!$F14+'ECOLES INTERVENTION'!$H14)/3) -> 5.0666667 | L14: Pass | M14: 1
A15: 6 | B15: Badaria Mani | D15: 5.4 | F15: 4.62 | H15: 4.95 | J15: =(('ECOLES INTERVENTION'!$D15+'ECOLES INTERVENTION'!$F15+'ECOLES INTERVENTION'!$H15)/3) -> 4.99 | L15: Passe | M15: 1
A16: 7 | B16: Mariama Souley | D16: 4.25 | F16: 5.15 | H16: 6 | J16: =(('ECOLES INTERVENTION'!$D16+'ECOLES INTERVENTION'!$F16+'ECOLES INTERVENTION'!$H16)/3) -> 5.1333333 | L16: Passe | M16: 1
A17: 8 | B17: Amira Illa | D17: 3.88 | F17: 4.79 | H17: 5 | J17: =(('ECOLES INTERVENTION'!$D17+'ECOLES INTERVENTION'!$F17+'ECOLES INTERVENTION'!$H17)/3) -> 4.5566667 | L17: Passe | M17: 1
A18: 9 | B18: Naima Boukari | D18: 4.5 | F18: 5 | H18: 4.65 | J18: =(('ECOLES INTERVENTION'!$D18+'ECOLES INTERVENTION'!$F18+'ECOLES INTERVENTION'!$H18)/3) -> 4.7166667 | L18: Passe | M18: 1
A19: 10 | B19: Badaria Souley | D19: 2.95 | F19: 2.75 | H19: 3.65 | J19: =(('ECOLES INTERVENTION'!$D19+'ECOLES INTERVENTION'!$F19+'ECOLES INTERVENTION'!$H19)/3) -> 3.1166667 | L19: Redouble | N19: 1
A20: 11 | B20: Hanifa Sabiou | D20: 3.6 | F20: 4.25 | H20: 6 | J20: =(('ECOLES INTERVENTION'!$D20+'ECOLES INTERVENTION'!$F20+'ECOLES INTERVENTION'!$H20)/3) -> 4.6166667 | L20: Passe | M20: 1
A21: 12 | B21: Wassila Chaibou | D21: 6.5 | F21: 6.9 | H21: 7.15 | J21: =(('ECOLES INTERVENTION'!$D21+'ECOLES INTERVENTION'!$F21+'ECOLES INTERVENTION'!$H21)/3) -> 6.85 | L21: Passe | M21: 1
A22: 13 | B22: Badaria Illia | D22: 4.75 | F22: 5 | H22: 5.69 | J22: =(('ECOLES INTERVENTION'!$D22+'ECOLES INTERVENTION'!$F22+'ECOLES INTERVENTION'!$H22)/3) -> 5.1466667 | L22: Passe | M22: 1
A23: 14 | B23: Oubeida Oumarou | D23: 3.9 | F23: 4.65 | H23: 4.95 | J23: =(('ECOLES INTERVENTION'!$D23+'ECOLES INTERVENTION'!$F23+'ECOLES INTERVENTION'!$H23)/3) -> 4.5 | L23: Passe | M23: 1
A24: 15 | B24: Noussaiba illa | D24: 4.6 | F24: 3.95 | H24: 5.25 | J24: =(('ECOLES INTERVENTION'!$D24+'ECOLES INTERVENTION'!$F24+'ECOLES INTERVENTION'!$H24)/3) -> 4.6 | L24: Passe | M24: 1
A25: 16 | B25: Safaraou Daouda | D25: 5 | F25: 6 | H25: 6.45 | J25: =(('ECOLES INTERVENTION'!$D25+'ECOLES INTERVENTION'!$F25+'ECOLES INTERVENTION'!$H25)/3) -> 5.8166667 | L25: Passe | M25: 1
A26: 17 | B26: Chikouriya Siradji | D26: 3.88 | F26: 4.69 | H26: 4.97 | J26: =(('ECOLES INTERVENTION'!$D26+'ECOLES INTERVENTION'!$F26+'ECOLES INTERVENTION'!$H26)/3) -> 4.5133333 | L26: Passe | M26: 1
A27: 18 | B27: Koubra Issa | D27: 4.35 | F27: 3.97 | H27: 5.25 | J27: =(('ECOLES INTERVENTION'!$D27+'ECOLES INTERVENTION'!$F27+'ECOLES INTERVENTION'!$H27)/3) -> 4.5233333 | L27: Passe | M27: 1
A28: 19 | B28: Charifa Abou | D28: 3 | F28: 5 | H28: 6.15 | J28: =(('ECOLES INTERVENTION'!$D28+'ECOLES INTERVENTION'!$F28+'ECOLES INTERVENTION'!$H28)/3) -> 4.7166667 | L28: Passe | M28: 1
A29: 20 | B29: Massaouda Sabiou | D29: 4.74 | F29: 6 | H29: 7 | J29: =(('ECOLES INTERVENTION'!$D29+'ECOLES INTERVENTION'!$F29+'ECOLES INTERVENTION'!$H29)/3) -> 5.9133333 | L29: Passe | M29: 1
M30: =SUM(M10:M29) -> 18 | N30: =SUM(N10:N29) -> 2
M31: =M30/A29 -> 0.9 | N31: =N30/A29 -> 0.1
A32: ECOLE DE DAN GAMJI
A33: 1 | B33: Hadiza Elhadji Issaka | D33: 3.2 | F33: 4.15 | H33: 5.89 | J33: =(('ECOLES INTERVENTION'!$D33+'ECOLES INTERVENTION'!$F33+'ECOLES INTERVENTION'!$H33)/3) -> 4.4133333 | L33: Passe | M33: 1
A34: 2 | B34: Firdaoussi Sanoussi | D34: 4.4 | F34: 4.87 | H34: 4.99 | J34: =(('ECOLES INTERVENTION'!$D34+'ECOLES INTERVENTION'!$F34+'ECOLES INTERVENTION'!$H34)/3) -> 4.7533333 | L34: Passe | M34: 1
A35: 3 | B35: Roufaida Rabé | D35: 4 | F35: 5 | H35: 6 | J35: =(('ECOLES INTERVENTION'!$D35+'ECOLES INTERVENTION'!$F35+'ECOLES INTERVENTION'!$H35)/3) -> 5 | L35: Pase | M35: 1
A36: 4 | B36: Badiya Sani | D36: 5.25 | F36: 6 | H36: 5.59 | J36: =(('ECOLES INTERVENTION'!$D36+'ECOLES INTERVENTION'!$F36+'ECOLES INTERVENTION'!$H36)/3) -> 5.6133333 | L36: Passe | M36: 1
A37: 5 | B37: Chappa Issiya | D37: 3.98 | F37: 4.57 | H37: 4.99 | J37: =(('ECOLES INTERVENTION'!$D37+'ECOLES INTERVENTION'!$F37+'ECOLES INTERVENTION'!$H37)/3) -> 4.5133333 | L37: Passe | M37: 1
A38: 6 | B38: Ommi kabirou | D38: 5.3 | F38: 5.5 | H38: 6.13 | J38: =(('ECOLES INTERVENTION'!$D38+'ECOLES INTERVENTION'!$F38+'ECOLES INTERVENTION'!$H38)/3) -> 5.6433333 | L38: Passe | M38: 1
A39: 7 | B39: Aminatou Sahirou | D39: 3.86 | F39: 4.85 | H39: 5.02 | J39: =(('ECOLES INTERVENTION'!$D39+'ECOLES INTERVENTION'!$F39+'ECOLES INTERVENTION'!$H39)/3) -> 4.5766667 | L39: Passe | M39: 1
A40: 8 | B40: Amira Salissou | D40: 4.73 | F40: 5.07 | H40: 5.59 | J40: =(('ECOLES INTERVENTION'!$D40+'ECOLES INTERVENTION'!$F40+'ECOLES INTERVENTION'!$H40)/3) -> 5.13 | L40: Passe | M40: 1
...

Sheet ECOLES CONTROLES
A1: REPUBLIQUE DU NIGER | K1: 7.21
A2: FRATERNITÉ - TRAVAIL - PROGRÈS
A3: REGION DE MARADI
A4: DIRECTION REGIONALE DE L'EDUCATION NATIONALE,
A5: DE L'ALPHABETISATION ET DE LA PROMOTION DES LANGUES
A6: IEP DE TCHADOUA
A7: Colonne1 | B7: Colonne2 | C7: Colonne3 | D7: Colonne4 | E7: Colonne6 | F7: Colonne8 | G7: Colonne10 | H7: Colonne12
A8: Ecole Guidan Tambari | I8: Passe en CM2 | J8: Redoublement | K8: Abandon | L8: Décès et transfère
A9: N° | B9: Noms et prénoms | D9: Moyenne 1er semestre | E9: Moyenne 2 ème semestre | F9: 3ème semestre | G9: Moyenne générale | H9: Situation finale
A10: 1 | B10: Mansoura Ibrahim | D10: 4.84 | E10: 4.96 | F10: 5.2 | G10: =(('ECOLES CONTROLES'!$D10+'ECOLES CONTROLES'!$E10+'ECOLES CONTROLES'!$F10)/3) -> 5 | H10: Passe | I10: 1
A11: 2 | B11: Houela Chaibou | D11: 3.34 | E11: 5.54 | F11: 6.12 | G11: =(('ECOLES CONTROLES'!$D11+'ECOLES CONTROLES'!$E11+'ECOLES CONTROLES'!$F11)/3) -> 5 | H11: Passe | I11: 1
A12: 3 | B12: Chamsiya Issa | D12: 4.47 | E12: 6.58 | F12: 7.38 | G12: =(('ECOLES CONTROLES'!$D12+'ECOLES CONTROLES'!$E12+'ECOLES CONTROLES'!$F12)/3) -> 6.1433333 | H12: Passe | I12: 1
A13: 4 | B13: Oubeida Adamou | D13: 3.88 | E13: 4.64 | F13: 5 | G13: =(('ECOLES CONTROLES'!$D13+'ECOLES CONTROLES'!$E13+'ECOLES CONTROLES'!$F13)/3) -> 4.5066667 | H13: Passe | I13: 1
A14: 5 | B14: Badaria Issoufou | D14: 1.78 | E14: 1.96 | F14: 2.07 | G14: =(('ECOLES CONTROLES'!$D14+'ECOLES CONTROLES'!$E14+'ECOLES CONTROLES'!$F14)/3) -> 1.9366667 | H14: Redouble | J14: 1
A15: 6 | B15: Rafia Ibrahim | D15: 4.21 | E15: 4.5 | F15: 5.08 | G15: =(('ECOLES CONTROLES'!$D15+'ECOLES CONTROLES'!$E15+'ECOLES CONTROLES'!$F15)/3) -> 4.5966667 | H15: Passe | I15: 1
A16: 7 | B16: Naima Harouna | D16: 4.69 | E16: 5.78 | F16: 4 | G16: =(('ECOLES CONTROLES'!$D16+'ECOLES CONTROLES'!$E16+'ECOLES CONTROLES'!$F16)/3) -> 4.8233333 | H16: Passe | I16: 1
A17: 8 | B17: Dinaou Ali | D17: 1.39 | E17: 1.46 | F17: 1.5 | G17: =(('ECOLES CONTROLES'!$D17+'ECOLES CONTROLES'!$E17+'ECOLES CONTROLES'!$F17)/3) -> 1.45 | H17: Redouble | J17: 1
A18: 9 | B18: Rakia Abou | D18: 0.47 | E18: 1.12 | F18: 0.96 | G18: =(('ECOLES CONTROLES'!$D18+'ECOLES CONTROLES'!$E18+'ECOLES CONTROLES'!$F18)/3) -> 0.85 | H18: Redouble | J18: 1
A19: 10 | B19: Bassira Illia | D19: 3.43 | E19: 3.18 | F19: 3.5 | G19: =(('ECOLES CONTROLES'!$D19+'ECOLES CONTROLES'!$E19+'ECOLES CONTROLES'!$F19)/3) -> 3.37 | H19: Redouble | J19: 1
A20: 11 | B20: Makkale Ali | D20: 5.65 | E20: 5.28 | F20: 5.08 | G20: =(('ECOLES CONTROLES'!$D20+'ECOLES CONTROLES'!$E20+'ECOLES CONTROLES'!$F20)/3) -> 5.3366667 | H20: Passe | I20: 1
A21: 12 | B21: Nafissa Soumeila | D21: 2.17 | E21: 2 | F21: 3.15 | G21: =(('ECOLES CONTROLES'!$D21+'ECOLES CONTROLES'!$E21+'ECOLES CONTROLES'!$F21)/3) -> 2.44 | H21: Redouble | J21: 1
I22: =SUM(I10:I21) -> 7 | J22: =SUM(J10:J21) -> 5
I23: =I22/A21 -> 0.58333333 | J23: =J22/A21 -> 0.41666667
A24: Ecole Dan Bouzou
A25: 1 | B25: Rouzeina Inoussa | D25: 4.25 | E25: 5.31 | F25: 5.8 | G25: =(('ECOLES CONTROLES'!$D25+'ECOLES CONTROLES'!$E25+'ECOLES CONTROLES'!$F25)/3) -> 5.12 | H25: Passe | I25: 1
A26: 2 | B26: Aichatou Abdou | D26: 5.75 | E26: 4.62 | F26: 4.89 | G26: =(('ECOLES CONTROLES'!$D26+'ECOLES CONTROLES'!$E26+'ECOLES CONTROLES'!$F26)/3) -> 5.0866667 | H26: Passe | I26: 1
A27: 3 | B27: Fatima Binia | D27: 3.85 | E27: 3.98 | F27: 5.71 | G27: =(('ECOLES CONTROLES'!$D27+'ECOLES CONTROLES'!$E27+'ECOLES CONTROLES'!$F27)/3) -> 4.5133333 | H27: Passe | I27: 1
A28: 4 | B28: Chamsia Ousseini | D28: // | E28: 2.09 | F28: 2.14 | G28: =(('ECOLES CONTROLES'!$E28+'ECOLES CONTROLES'!$F28)/3) -> 1.41 | H28: Abondon | K28: 1
A29: 5 | B29: Charifa Ali | D29: 1.81 | E29: 2.07 | F29: 2.37 | G29: =(('ECOLES CONTROLES'!$D29+'ECOLES CONTROLES'!$E29+'ECOLES CONTROLES'!$F29)/3) -> 2.0833333 | H29: Redouble | J29: 1
A30: 6 | B30: Yassira Issa | D30: 5 | E30: 5.12 | F30: 5.69 | G30: =(('ECOLES CONTROLES'!$D30+'ECOLES CONTROLES'!$E30+'ECOLES CONTROLES'!$F30)/3) -> 5.27 | H30: Passe | I30: 1
A31: 7 | B31: Aichatou Mounkaila | D31: 4.75 | E31: 3.85 | F31: 4.95 | G31: =(('ECOLES CONTROLES'!$D31+'ECOLES CONTROLES'!$E31+'ECOLES CONTROLES'!$F31)/3) -> 4.5166667 | H31: Passe | I31: 1
A32: 8 | B32: Azima Larwana | D32: 3.4 | E32: 4.62 | F32: 3.87 | G32: =(('ECOLES CONTROLES'!$D32+'ECOLES CONTROLES'!$E32+'ECOLES CONTROLES'!$F32)/3) -> 3.9633333 | H32: Redouble | J32: 1
A33: 9 | B33: Zeinabou Maazou | D33: 4.62 | E33: 4.12 | F33: 5.26 | G33: =(('ECOLES CONTROLES'!$D33+'ECOLES CONTROLES'!$E33+'ECOLES CONTROLES'!$F33)/3) -> 4.6666667 | H33: Passe | I33: 1
A34: 10 | B34: Aichatou Maman | D34: 3.5 | E34: 2.5 | F34: Absente | G34: =(('ECOLES CONTROLES'!$D34+'ECOLES CONTROLES'!$E34)/3) -> 2 | H34: Redouble | J34: 1
A35: 11 | B35: Nafissa Haladou | D35: 4.87 | E35: 5.07 | F35: 6 | G35: =(('ECOLES CONTROLES'!$D35+'ECOLES CONTROLES'!$E35+'ECOLES CONTROLES'!$F35)/3) -> 5.3133333 | H35: Passe | I35: 1
A36: 12 | B36: Hannatou Tassiou | D36: 1.5 | E36: 2.85 | F36: 2.87 | G36: =(('ECOLES CONTROLES'!$D36+'ECOLES CONTROLES'!$E36+'ECOLES CONTROLES'!$F36)/3) -> 2.4066667 | H36: Redouble | J36: 1
A37: 13 | B37: Hakima Ibrahim | D37: 3.59 | E37: 4.8 | F37: 5.4 | G37: =(('ECOLES CONTROLES'!$D37+'ECOLES CONTROLES'!$E37+'ECOLES CONTROLES'!$F37)/3) -> 4.5966667 | H37: Passe | I37: 1
A38: 14 | B38: Nafiza Abdoul Aziz | D38: 4.72 | E38: 5 | F38: 4.91 | G38: =(('ECOLES CONTROLES'!$D38+'ECOLES CONTROLES'!$E38+'ECOLES CONTROLES'!$F38)/3) -> 4.8766667 | H38: Passe | I38: 1
A39: 15 | B39: Mouniba Moutari | D39: 1.5 | E39: 2.12 | F39: 2.7 | G39: =(('ECOLES CONTROLES'!$D39+'ECOLES CONTROLES'!$E39+'ECOLES CONTROLES'!$F39)/3) -> 2.1066667 | H39: Redouble | J39: 1
A40: 16 | B40: Latifa Abdou | D40: 4 | E40: 4.81 | F40: 4.99 | G40: =(('ECOLES CONTROLES'!$D40+'ECOLES CONTROLES'!$E40+'ECOLES CONTROLES'!$F40)/3) -> 4.6 | H40: Passe | I40: 1
...

Sheet Liste classement écoles interve
A1: Tchadoua liste des écoles interventions CM1 | B1: Taux de réssite | C1: Classement des écoles interventions selon leurs taux de réussite | G1: Tchadoua liste des écoles interventions CM1 | H1: Taux de réssite
A2: ZANGON NA RUWA | B2: 0.9 | C2: 10ème | G2: GUIDAN MAGAGI | H2: 1
A3: DAN GAMJI | B3: 0.91428571 | C3: 8ème | G3: DOUMA 1 | H3: 0.96296296
A4: KURAN MOTA | B4: 0.90909091 | C4: 9ème | G4: TAWALALA | H4: 0.95833333
A5: GUIDAN KARMA | B5: 0.94444444 | C5: 4ème | G5: GUIDAN KARMA | H5: 0.94444444
A6: DAN AICHA | B6: 0.9 | C6: 10ème execo | G6: GUIDAN MOUSSA | H6: 0.9375
A7: GUIDAN MAGAGI | B7: 1 | C7: 1ère | G7: MAI JANGUERO | H7: 0.92307692
A8: GAWARO MADATTAI | B8: 0.92307692 | C8: 6ème | G8: GAWARO MADATTAI | H8: 0.92307692
A9: MAI JANGUERO | B9: 0.92307692 | C9: 6ème execo | G9: JAN RUWA SEDENTAIRE | H9: 0.91666667
A10: JAN RUWA SEDENTAIRE | B10: 0.91666667 | C10: 7ème | G10: DAN GAMJI | H10: 0.91428571
A11: TAWALALA | B11: 0.95833333 | C11: 3ème | G11: KURAN MOTA | H11: 0.90909091
A12: GUIDAN MOUSSA | B12: 0.9375 | C12: 5ème | G12: ZANGON NA RUWA | H12: 0.9
A13: DOUMA 1 | B13: 0.96296296 | C13: 2ème | G13: DAN AICHA | H13: 0.9

Sheet Analyse Tchadoua CM1 
A1: Tchadoua | B1: Total inscrites CM1 | C1: Nombre passe CM2 | D1: Nombre abadon CM1 | E1: Taux de passage CM2 | F1: Taux d'abandon CM1
A2: Intervention | B2: 302 | C2: 280 | D2: 0 | E2: =C2/B2 -> 0.92715232 | F2: =D2/B2 -> 0
A3: Controle | B3: 202 | C3: 124 | D3: 7 | E3: =C3/B3 -> 0.61386139 | F3: =D3/B3 -> 0.034653465

Sheet Graphique des resultats
B5: Les écoles d'intervention
A6: N°d'ordre
B7: Ecole | C7: Effectifs | D7: Redouble | E7: Passe | F7: Pourcentage
A8: 1 | B8: Zangon Na Ruwa | C8: 20 | D8: 2 | E8: 18 | F8: 0.9
A9: 2 | B9: Dan Gamji | C9: 35 | D9: 3 | E9: 32 | F9: 0.9142
A10: 3 | B10: Kuran Mota | C10: 22 | D10: 2 | E10: 20 | F10: 0.909
A11: 4 | B11: Guidan Karma | C11: 18 | D11: 1 | E11: 17 | F11: 0.9444
A12: 5 | B12: Dan Aicha | C12: 30 | D12: 3 | E12: 27 | F12: 0.9
A13: 6 | B13: Guidan Magagi | C13: 18 | D13: 0 | E13: 100 | F13: 1
A14: 7 | B14: Gawaro Madattai | C14: 26 | D14: 2 | E14: 24 | F14: 0.923
A15: 8 | B15: Mai Janguero | C15: 26 | D15: 2 | E15: 24 | F15: 0.923
A16: 9 | B16: Jan Ruwa Sedentaire | C16: 24 | D16: 2 | E16: 22 | F16: 0.9166
A17: 10 | B17: Tawalala | C17: 24 | D17: 1 | E17: 23 | F17: 0.9583
A18: 11 | B18: Guidan Moussa | C18: 32 | D18: 2 | E18: 30 | F18: 0.9375
A19: 12 | B19: Douma 1 | C19: 27 | D19: 2 | E19: 25 | F19: 0.9259
E20: =SUM(E8:E19) -> 362
B22: Les écoles de contrôle
A23: N°d'ordre
B24: Ecole | C24: Effectifs | D24: Redouble | E24: Passe | F24: Pourcentage
A25: 1 | B25: Guidan Tambari | C25: 12 | D25: 5 | E25: 7 | F25: 0.5833
A26: 2 | B26: Dan Bouzou | C26: 20 | D26: 6 | E26: 12 | F26: 0.6666
A27: 3 | B27: Wakasso | C27: 20 | D27: 7 | E27: 13 | F27: 0.65
A28: 4 | B28: Guidan Dan Galadima | C28: 23 | D28: 7 | E28: 16 | F28: 0.6956
A29: 5 | B29: Zabon Mousso | C29: 12 | D29: 5 | E29: 7 | F29: 0.5833
A30: 6 | B30: Bini | C30: 14 | D30: 6 | E30: 8 | F30: 0.5714
A31: 7 | B31: Magami | C31: 14 | D31: 6 | E31: 8 | F31: 0.5714
A32: 8 | B32: Guidan Zoudi | C32: 15 | D32: 6 | E32: 6 | F32: 0.5
A33: 9 | B33: Dan Tumbi | C33: 29 | D33: 8 | E33: 19 | F33: 0.7037
A34: 10 | B34: Kotsi(Algafia) | C34: 17 | D34: 6 | E34: 11 | F34: 0.647
A35: 11 | B35: Chapké | C35: 15 | D35: 5 | E35: 9 | F35: 0.6428
A36: 12 | B36: Guidan Koubé | C36: 11 | D36: 5 | E36: 6 | F36: 0.5454
E37: =SUM(E25:E36) -> 122
