Workbook

Sheet CM1
A1: REPUBLIQUE DU NIGER
A2: REGION DE MARADI
A3: DREN MARADI
A4: IEPP SAE SABOUA
A6: LISTE DES ELEVES FILLES DU CM1
A8: N° | B8: ECOLE | C8: NOM ET PRENOMS | D8: MOYENNE | E8: OBSERVATION
A9: 1 | B9: Mallamaî Saboua | C9: Absiya Hamissou | D9: 6.75 | E9: Passe au CM2
A10: 2 | B10: Mallamaî Saboua | C10: Azoumiya Souley | D10: 5.25 | E10: Passe au CM2
A11: 3 | B11: Mallamaî Saboua | C11: Anissa Sani | D11: 5.25 | E11: Passe au CM2
A12: 4 | B12: Mallamaî Saboua | C12: Bassira Moussa | D12: 5.56 | E12: Passe au CM2
A13: 5 | B13: Mallamaî Saboua | C13: Bassira Yacouba | D13: 5.43 | E13: Passe au CM2
A14: 6 | B14: Mallamaî Saboua | C14: Chaâbiya Halilou | D14: 5.12 | E14: Passe au CM2
A15: 7 | B15: Mallamaî Saboua | C15: Chamsiya Iro | D15: 6.12 | E15: Passe au CM2
A16: 8 | B16: Mallamaî Saboua | C16: Charifa Idrissa | D16: 8.06 | E16: Passe au CM2
A17: 9 | B17: Mallamaî Saboua | C17: Djamila Oumarou | D17: 5.37 | E17: Passe au CM2
A18: 10 | B18: Mallamaî Saboua | C18: Fatima Abou | D18: 6.68 | E18: Passe au CM2
A19: 11 | B19: Mallamaî Saboua | C19: Houéla Hassan | D19: 8.68 | E19: Passe au CM2
A20: 12 | B20: Mallamaî Saboua | C20: Harissa Bassirou | D20: 4.5 | E20: Passe au CM2
... A147: 175 | B147: Barouana | C147: Zeinab Abdou | D147: 5.2 | E147: Passe au CM2
A148: Total | B148: =SUBTOTAL(103,'CM1'!$B$9:$B$147) -> 132 | D148: =SUBTOTAL(101,'CM1'!$D$9:$D$147) -> 5.9454545

Sheet CM2
A8: ECOLE | B8: NOM ET PRENOMS | C8: MOYENNE | D8: OBSERVATION
A9: Barouana | B9: Aminatou Abdou | C9: 1 | D9: Redouble au CM2
A10: Barouana | B10: Zoubeida Hamissou | C10: 0.32142857 | D10: Redouble au CM2
A11: Barouana | B11: Charifa Ibrahim | C11: 0.46428571 | D11: Redouble au CM2
A12: Barouana | B12: Assamaou Hassan | C12: 0.5 | D12: Redouble au CM2
A13: Barouana | B13: Fatiha Illiyassou | C13: 0.60714286 | D13: Redouble au CM2
A14: Barouana | B14: Mardiya Ousseini | C14: 0.75 | D14: Redouble au CM2
A15: Barouana | B15: Soueba Almou | C15: 0.92857143 | D15: Redouble au CM2
A16: Barouana | B16: Rafi'a Illa | C16: 1.0357143 | D16: Redouble au CM2
A17: Barouana | B17: Chamsiya Sanoussi | C17: 1.0714286 | D17: Redouble au CM2
A18: Barouana | B18: Firdaoussi Halilou | C18: 1.1428571 | D18: Redouble au CM2
A19: Barouana | B19: Laritou Abdou | C19: 1.3571429 | D19: Redouble au CM2
A20: Barouana | B20: Rayya Abdou | C20: 1.375 | D20: Redouble au CM2
... A240: Saé Saboua Publique 1 | B240: Ousseina Saâdou | C240: 5.1428571 | D240: Passe au CEG
A241: Saé Saboua Publique 1 | B241: Liyaâtou Tsayabou | C241: 7.0357143 | D241: Passe au CEG | G241: 9
A242: Saé Saboua Publique 1 | B242: Alawiya Alka | C242: 7.5357143 | D242: Passe au CEG
A243: Saé Saboua Publique 1 | B243: Yassira Zabeirou | C243: 7.875 | D243: Passe au CEG
A244: Saé Saboua Publique 1 | B244: Mafida Rabiou | C244: 8.1071429 | D244: Passe au CEG
A245: Saé Saboua Publique 1 | B245: Mouhssina Tsayabou | C245: 8.5714286 | D245: Passe au CEG
A246: Saé Saboua Publique 1 | B246: Aminatou Moussa Labo | C246: 8.7142857 | D246: Passe au CEG
A247: Saé Saboua Publique 1 | B247: Ramatou Hamza | C247: 0.71428571 | D247: Redouble au CM2
A248: Saé Saboua Publique 1 | B248: Halimatou Inoussa | C248: 1 | D248: Redouble au CM2
A249: Saé Saboua Publique 1 | B249: Samira Boukari | C249: 1.1964286 | D249: Redouble au CM2
A250: Saé Saboua Publique 1 | B250: Nana Mariama Oumarou | C250: 1.2857143 | D250: Redouble au CM2
A251: Saé Saboua Publique 1 | B251: Yasmina Boukari | C251: 1.3571429 | D251: Passe au CFM
A252: Saé Saboua Publique 1 | B252: Oumaïmatou Hassan | C252: 1.6428571 | D252: Redouble au CM2
A253: Saé Saboua Publique 1 | B253: Madjida Issaka | C253: 1.7142857 | D253: Redouble au CM2
... A278: Tagaza | B278: Faïza Abdoul Salam | C278: 5.0178571 | D278: Passe au CEG
A279: Tagaza | B279: Souraya Nouhou | C279: 5.0357143 | D279: Passe au CEG | G279: 6
A280: Tagaza | B280: Naima Abdou | C280: 5.0357143 | D280: Passe au CEG
A281: Tagaza | B281: Bassira Sani | C281: 5.2857143 | D281: Passe au CEG
A282: Tagaza | B282: Kadidja Zabeirou | C282: 1 | D282: Redouble au CM2
A283: Tagaza | B283: Chappa Hachimou | C283: 1.0357143 | D283: Redouble au CM2
A284: Tagaza | B284: Mabachara Almoustapha | C284: 1.0714286 | D284: Redouble au CM2
A285: Tagaza | B285: Nafissa Mamane | C285: 1.4285714 | D285: Redouble au CM2
A286: Tagaza | B286: Wassila Ayouba | C286: 1.5178571 | D286: Redouble au CM2
A287: Tagaza | B287: Kadidja Halilou | C287: 1.5357143 | D287: Redouble au CM2
A288: Tagaza | B288: lamsiya Mamane | C288: 1.5357143 | D288: Redouble au CM2
A289: Tagaza | B289: Amira Sani | C289: 1.5714286 | D289: Redouble au CM2
A290: Tagaza | B290: Mastoura Mamane | C290: 1.5714286 | D290: Redouble au CM2
...

Sheet CM1 & CM2 Metrics
E2: CM1
A3: Ecole | B3: Insrites | C3: Abandonee # | D3: Presentes | E3: Admises # | F3: Non Admise # | G3: Abandonee % | H3: Admises % | I3: Non Admise % | J3: Comments
A4: Barouana | B4: 15 | C4: 0 | D4: 15 | E4: 15 | F4: 0 | G4: 0 | H4: ='CM1 & CM2 Metrics'!$E4/'CM1 & CM2 Metrics'!$D4 -> 1 | I4: ='CM1 & CM2 Metrics'!$F4/'CM1 & CM2 Metrics'!$B4 -> 0 | J4: No Abandon metric
A5: Kadata | B5: 23 | C5: 0 | D5: 23 | E5: 23 | F5: 0 | G5: 0 | H5: ='CM1 & CM2 Metrics'!$E5/'CM1 & CM2 Metrics'!$D5 -> 1 | I5: ='CM1 & CM2 Metrics'!$F5/'CM1 & CM2 Metrics'!$B5 -> 0
A6: Kadigaoua | B6: 12 | C6: 0 | D6: 12 | E6: 12 | F6: 0 | G6: 0 | H6: ='CM1 & CM2 Metrics'!$E6/'CM1 & CM2 Metrics'!$D6 -> 1 | I6: ='CM1 & CM2 Metrics'!$F6/'CM1 & CM2 Metrics'!$B6 -> 0
A7: Louloubi Publique | B7: 17 | C7: 0 | D7: 17 | E7: 17 | F7: 0 | G7: 0 | H7: ='CM1 & CM2 Metrics'!$E7/'CM1 & CM2 Metrics'!$D7 -> 1 | I7: ='CM1 & CM2 Metrics'!$F7/'CM1 & CM2 Metrics'!$B7 -> 0
A8: Mallamai Saboua | B8: 30 | C8: 0 | D8: 30 | E8: 30 | F8: 0 | G8: 0 | H8: ='CM1 & CM2 Metrics'!$E8/'CM1 & CM2 Metrics'!$D8 -> 1 | I8: ='CM1 & CM2 Metrics'!$F8/'CM1 & CM2 Metrics'!$B8 -> 0
A9: Mountarou Barmo | B9: 12 | C9: 0 | D9: 12 | E9: 12 | F9: 0 | G9: 0 | H9: ='CM1 & CM2 Metrics'!$E9/'CM1 & CM2 Metrics'!$D9 -> 1 | I9: ='CM1 & CM2 Metrics'!$F9/'CM1 & CM2 Metrics'!$B9 -> 0
A10: Oubandawaki Alfacha | B10: 30 | C10: 0 | D10: 30 | E10: 23 | F10: 7 | G10: 0 | H10: ='CM1 & CM2 Metrics'!$E10/'CM1 & CM2 Metrics'!$D10 -> 0.76666667 | I10: ='CM1 & CM2 Metrics'!$F10/'CM1 & CM2 Metrics'!$B10 -> 0.23333333
A11: Total | B11: =SUBTOTAL(109,'CM1 & CM2 Metrics'!$B$4:$B$10) -> 139 | C11: =SUBTOTAL(109,'CM1 & CM2 Metrics'!$C$4:$C$10) -> 0 | D11: =SUBTOTAL(109,'CM1 & CM2 Metrics'!$D$4:$D$10) -> 139 | E11: =SUBTOTAL(109,'CM1 & CM2 Metrics'!$E$4:$E$10) -> 132 | F11: =SUBTOTAL(109,'CM1 & CM2 Metrics'!$F$4:$F$10) -> 7 | H11: ='CM1 & CM2 Metrics'!$E$11/'CM1 & CM2 Metrics'!$D$11 -> 0.94964029 | I11: ='CM1 & CM2 Metrics'!$F$11/'CM1 & CM2 Metrics'!$D$11 -> 0.050359712
E18: CM2
A19: Ecole | B19: Insrites | C19: Abandonee # | D19: Presentes | E19: Admises # | F19: Non Admise # | G19: Abandonee % | H19: Admises % | I19: Non Admise % | J19: Comments
A20: Barouana | B20: 27 | C20: 0 | D20: 27 | E20: 9 | F20: ='CM1 & CM2 Metrics'!$D20-'CM1 & CM2 Metrics'!$E20 -> 18 | G20: 0 | H20: ='CM1 & CM2 Metrics'!$E20/'CM1 & CM2 Metrics'!$D20 -> 0.33333333 | I20: ='CM1 & CM2 Metrics'!$F20/'CM1 & CM2 Metrics'!$B20 -> 0.66666667
A21: Dan Gamdji | B21: 50 | C21: 0 | D21: 50 | E21: 19 | F21: ='CM1 & CM2 Metrics'!$D21-'CM1 & CM2 Metrics'!$E21 -> 31 | G21: 0 | H21: ='CM1 & CM2 Metrics'!$E21/'CM1 & CM2 Metrics'!$D21 -> 0.38 | I21: ='CM1 & CM2 Metrics'!$F21/'CM1 & CM2 Metrics'!$B21 -> 0.62
A22: Kadata | B22: 25 | C22: 0 | D22: 25 | E22: 11 | F22: ='CM1 & CM2 Metrics'!$D22-'CM1 & CM2 Metrics'!$E22 -> 14 | G22: 0 | H22: ='CM1 & CM2 Metrics'!$E22/'CM1 & CM2 Metrics'!$D22 -> 0.44 | I22: ='CM1 & CM2 Metrics'!$F22/'CM1 & CM2 Metrics'!$B22 -> 0.56
A23: Kadigaoua | B23: 18 | C23: 0 | D23: 18 | E23: 10 | F23: ='CM1 & CM2 Metrics'!$D23-'CM1 & CM2 Metrics'!$E23 -> 8 | G23: 0 | H23: ='CM1 & CM2 Metrics'!$E23/'CM1 & CM2 Metrics'!$D23 -> 0.55555556 | I23: ='CM1 & CM2 Metrics'!$F23/'CM1 & CM2 Metrics'!$B23 -> 0.44444444
A24: Kountarou Mairairai | B24: 19 | C24: 1 | D24: 18 | E24: 4 | F24: ='CM1 & CM2 Metrics'!$D24-'CM1 & CM2 Metrics'!$E24 -> 14 | G24: ='CM1 & CM2 Metrics'!$C24/'CM1 & CM2 Metrics'!$B24 -> 0.052631579 | H24: ='CM1 & CM2 Metrics'!$E24/'CM1 & CM2 Metrics'!$D24 -> 0.22222222 | I24: ='CM1 & CM2 Metrics'!$F24/'CM1 & CM2 Metrics'!$B24 -> 0.73684211
A25: Louloubi Publique | B25: 32 | C25: 2 | D25: 30 | E25: 11 | F25: ='CM1 & CM2 Metrics'!$D25-'CM1 & CM2 Metrics'!$E25 -> 19 | G25: ='CM1 & CM2 Metrics'!$C25/'CM1 & CM2 Metrics'!$B25 -> 0.0625 | H25: ='CM1 & CM2 Metrics'!$E25/'CM1 & CM2 Metrics'!$D25 -> 0.36666667 | I25: ='CM1 & CM2 Metrics'!$F25/'CM1 & CM2 Metrics'!$B25 -> 0.59375
A26: Mallamai Saboua | B26: 21 | C26: 0 | D26: 21 | E26: 9 | F26: ='CM1 & CM2 Metrics'!$D26-'CM1 & CM2 Metrics'!$E26 -> 12 | G26: 0 | H26: ='CM1 & CM2 Metrics'!$E26/'CM1 & CM2 Metrics'!$D26 -> 0.42857143 | I26: ='CM1 & CM2 Metrics'!$F26/'CM1 & CM2 Metrics'!$B26 -> 0.57142857
A27: Mountarou Barmo | B27: 20 | C27: 0 | D27: 20 | E27: 13 | F27: ='CM1 & CM2 Metrics'!$D27-'CM1 & CM2 Metrics'!$E27 -> 7 | G27: 0 | H27: ='CM1 & CM2 Metrics'!$E27/'CM1 & CM2 Metrics'!$D27 -> 0.65 | I27: ='CM1 & CM2 Metrics'!$F27/'CM1 & CM2 Metrics'!$B27 -> 0.35
A28: Oubandawaki Alfacha | B28: 17 | C28: 0 | D28: 17 | E28: 11 | F28: ='CM1 & CM2 Metrics'!$D28-'CM1 & CM2 Metrics'!$E28 -> 6 | G28: 0 | H28: ='CM1 & CM2 Metrics'!$E28/'CM1 & CM2 Metrics'!$D28 -> 0.64705882 | I28: ='CM1 & CM2 Metrics'!$F28/'CM1 & CM2 Metrics'!$B28 -> 0.35294118
A29: Saé Saboua Publique 1 | B29: 38 | C29: 0 | D29: 38 | E29: 15 | F29: ='CM1 & CM2 Metrics'!$D29-'CM1 & CM2 Metrics'!$E29 -> 23 | G29: 0 | H29: ='CM1 & CM2 Metrics'!$E29/'CM1 & CM2 Metrics'!$D29 -> 0.39473684 | I29: ='CM1 & CM2 Metrics'!$F29/'CM1 & CM2 Metrics'!$B29 -> 0.60526316
A30: Tagaza | B30: 29 | C30: 0 | D30: 29 | E30: 12 | F30: ='CM1 & CM2 Metrics'!$D30-'CM1 & CM2 Metrics'!$E30 -> 17 | G30: 0 | H30: ='CM1 & CM2 Metrics'!$E30/'CM1 & CM2 Metrics'!$D30 -> 0.4137931 | I30: ='CM1 & CM2 Metrics'!$F30/'CM1 & CM2 Metrics'!$B30 -> 0.5862069
A31: Total | B31: =SUBTOTAL(109,'CM1 & CM2 Metrics'!$B$20:$B$30) -> 296 | C31: =SUBTOTAL(109,'CM1 & CM2 Metrics'!$C$20:$C$30) -> 3 | D31: =SUBTOTAL(109,'CM1 & CM2 Metrics'!$D$20:$D$30) -> 293 | E31: =SUBTOTAL(109,'CM1 & CM2 Metrics'!$E$20:$E$30) -> 124 | F31: =SUBTOTAL(109,'CM1 & CM2 Metrics'!$F$20:$F$30) -> 169 | G31: ='CM1 & CM2 Metrics'!$C$31/'CM1 & CM2 Metrics'!$B$31 -> 0.010135135 | H31: ='CM1 & CM2 Metrics'!$E$31/'CM1 & CM2 Metrics'!$D$31 -> 0.42320819 | I31: ='CM1 & CM2 Metrics'!$F$31/'CM1 & CM2 Metrics'!$D$31 -> 0.57679181
