Workbook

Sheet CM1
A1: REPUBLIQUE DU NIGER
A2: REGION DE MARADI
A3: DREN MARADI
A4: IEPP SAE SABOUA
A6: LISTE DES ELEVES FILLES DU CM1 DES ECOLES TEMOINS LFF
A8: N° | B8: ECOLE | C8: NOM ET PRENOMS | D8: MOYENNE | E8: OBSERVATION
A9: 1 | B9: Mallamai Salifou | C9: Amatoulahi Badamassi | D9: 6.34 | E9: Passe au CM2
A10: 2 | B10: Mallamai Salifou | C10: Charifa Amadou | D10: 9.46 | E10: Passe au CM2
A11: 3 | B11: Mallamai Salifou | C11: Cha'awanatou Yahouza | D11: 7.67 | E11: Passe au CM2
A12: 4 | B12: Mallamai Salifou | C12: Faïza Rabiou | D12: 5.27 | E12: Passe au CM2
A13: 5 | B13: Mallamai Salifou | C13: Faouzia Salissou | D13: 4.57 | E13: Passe au CM2
A14: 6 | B14: Mallamai Salifou | C14: Fati Inoussa | D14: 5.31 | E14: Passe au CM2
A15: 7 | B15: Mallamai Salifou | C15: Fati Abdou | D15: 3.51 | E15: Redouble le CM1
A16: 8 | B16: Mallamai Salifou | C16: Hassana Hamidine | D16: 3.68 | E16: Redouble le CM1
A17: 9 | B17: Mallamai Salifou | C17: Moufida Saïdou | D17: 4.58 | E17: Passe au CM2
A18: 10 | B18: Mallamai Salifou | C18: Nachira Sani | D18: 4.56 | E18: Passe au CM2
A19: 11 | B19: Mallamai Salifou | C19: Nadiya Laminou | D19: 7.45 | E19: Passe au CM2
A20: 12 | B20: Mallamai Salifou | C20: Nana Sadika Zabeirou | D20: 3.8 | E20: Redouble le CM1
... A159: 151 | B159: Mata Milki | C159: Souéba Daouda | D159: 1.52 | E159: Redouble le CM1
A160: =SUBTOTAL(102,'CM1'!$A$9:$A$159) -> 151

Sheet CM2
A1: REPUBLIQUE DU NIGER
A2: REGION DE MARADI
A3: DREN MARADI
A4: IEPP SAE SABOUA
A6: SITUATION DES ELEVES FILLES DU CM2 DES ECOLES TEMOINS LFF
A8: N° | B8: ECOLE | C8: NOM ET PRENOMS | D8: MOYENNE GENERALE DE CLASSE | E8: OBSERVATION
B9: ECOLE DAN GARA
A10: 1 | B10: Dan Gara | C10: Aïnaou Yaou | D10: 2.83 | E10: Redouble le CM2
A11: 2 | B11: Dan Gara | C11: Amira Laouali | D11: 4.345 | E11: Passe au CFM
A12: 3 | B12: Dan Gara | C12: Azima Harouna | D12: 0 | E12: Passe au CFM
A13: 4 | B13: Dan Gara | C13: Baraâtou Oumarou | D13: 6.26 | E13: Redouble le CM2
A14: 5 | B14: Dan Gara | C14: Barira Djadi | D14: 6.555 | E14: Redouble le CM2
A15: 6 | B15: Dan Gara | C15: Chamsia Harouna | D15: 0 | E15: Redouble le CM2
A16: 7 | B16: Dan Gara | C16: Chamsia Saminou | D16: 7.065 | E16: Redouble le CM2
A17: 8 | B17: Dan Gara | C17: Charifa Harouna | D17: 6.425 | E17: Redouble le CM2
A18: 9 | B18: Dan Gara | C18: Choukouria Laouali | D18: 4.32 | E18: Passe au CFM
A19: 10 | B19: Dan Gara | C19: Faïza Abdou Rahamane | D19: 3.685 | E19: Passe au CFM
A20: 11 | B20: Dan Gara | C20: Farida Chaibou | D20: 3.585 | E20: Passe au CFM
A21: 12 | B21: Dan Gara | C21: Haouaou Adamou | D21: 4.365 | E21: Passe au CFM
... A48: 39 | B48: Dan Gara | C48: Zeinabou Rabe | D48: 4.085 | E48: Redouble le CM2
B49: ECOLE DAN BAKO
A50: 1 | B50: Dan Bako | C50: Amara Djibo | D50: 3.91 | E50: Redouble le CM2
A51: 2 | B51: Dan Bako | C51: Anifa Halilou | D51: 6.58 | E51: Redouble le CM2
A52: 3 | B52: Dan Bako | C52: Ara'a Idi | D52: 6.495 | E52: Redouble le CM2
A53: 4 | B53: Dan Bako | C53: Assibi Moussa | D53: 5.935 | E53: Redouble le CM2
A54: 5 | B54: Dan Bako | C54: Aziza Salissou | D54: 7.11 | E54: Redouble le CM2
A55: 6 | B55: Dan Bako | C55: Baraâtou Halilou | D55: 5.11 | E55: Redouble le CM2
A56: 7 | B56: Dan Bako | C56: Baraâtou Maâzou | D56: 3.64 | E56: Redouble le CM2
A57: 8 | B57: Dan Bako | C57: Bassira Illa | D57: 3.64 | E57: Redouble le CM2
A58: 9 | B58: Dan Bako | C58: Binta Issaka | D58: 5.82 | E58: Redouble le CM2
A59: 10 | B59: Dan Bako | C59: Chaffa Harouna | D59: 4 | E59: Redouble le CM2
A60: 11 | B60: Dan Bako | C60: Chaffaiya Almou | D60: 8.615 | E60: Passe au CEG
A61: 12 | B61: Dan Bako | C61: Chamsiya Abou | D61: 4.715 | E61: Redouble le CM2
... A113: 64 | B113: Dan Bako | C113: Zoubeida Issoufou | D113: 2.615 | E113: Redouble le CM2
B114: ECOLE ALSAWA
A115: 1 | B115: Alsawa | C115: Aïcha Issaka | D115: 5.275 | E115: Redouble le CM2
A116: 2 | B116: Alsawa | C116: Chamsiya Habibou | D116: 5.985 | E116: Passe au CEG
A117: 3 | B117: Alsawa | C117: Faouzia Saidou | D117: 8.285 | E117: Passe au CEG
A118: 4 | B118: Alsawa | C118: Fatiha Laouali | D118: 7.815 | E118: Passe au CEG
A119: 5 | B119: Alsawa | C119: Firdaoussi Ibrahim | D119: 3.06 | E119: Redouble le CM2
...

Sheet CM1 & CM2 Metrics
E4: CM1
A6: Ecole | B6: Insrites | C6: Abandonee # | D6: Presentes | E6: Admises # | F6: Non Admise # | G6: Abandonee % | H6: Admises % | I6: Non Admise % | J6: Comments
A7: Dan Bako | B7: 36 | C7: 0 | D7: 36 | E7: 23 | F7: 13 | G7: ='CM1 & CM2 Metrics'!$C7/'CM1 & CM2 Metrics'!$B7 -> 0 | H7: ='CM1 & CM2 Metrics'!$E7/'CM1 & CM2 Metrics'!$D7 -> 0.63888889 | I7: ='CM1 & CM2 Metrics'!$F7/'CM1 & CM2 Metrics'!$D7 -> 0.36111111
A8: Dan Gara | B8: 30 | C8: 0 | D8: 30 | E8: 23 | F8: =30-'CM1 & CM2 Metrics'!$E8 -> 7 | G8: ='CM1 & CM2 Metrics'!$C8/'CM1 & CM2 Metrics'!$B8 -> 0 | H8: ='CM1 & CM2 Metrics'!$E8/'CM1 & CM2 Metrics'!$D8 -> 0.76666667 | I8: ='CM1 & CM2 Metrics'!$F8/'CM1 & CM2 Metrics'!$D8 -> 0.23333333
A9: Mallamai Salifou | B9: 23 | C9: 0 | D9: 23 | E9: 15 | F9: ='CM1 & CM2 Metrics'!$D9-'CM1 & CM2 Metrics'!$E9 -> 8 | G9: ='CM1 & CM2 Metrics'!$C9/'CM1 & CM2 Metrics'!$B9 -> 0 | H9: ='CM1 & CM2 Metrics'!$E9/'CM1 & CM2 Metrics'!$D9 -> 0.65217391 | I9: ='CM1 & CM2 Metrics'!$F9/'CM1 & CM2 Metrics'!$D9 -> 0.34782609
A10: Mata Milki | B10: 40 | C10: 0 | D10: 40 | E10: 24 | F10: ='CM1 & CM2 Metrics'!$D10-'CM1 & CM2 Metrics'!$E10 -> 16 | G10: ='CM1 & CM2 Metrics'!$C10/'CM1 & CM2 Metrics'!$B10 -> 0 | H10: ='CM1 & CM2 Metrics'!$E10/'CM1 & CM2 Metrics'!$D10 -> 0.6 | I10: ='CM1 & CM2 Metrics'!$F10/'CM1 & CM2 Metrics'!$D10 -> 0.4
A11: Yan Doto Garin Malam | B11: 22 | C11: 0 | D11: 22 | E11: 13 | F11: ='CM1 & CM2 Metrics'!$D11-'CM1 & CM2 Metrics'!$E11 -> 9 | G11: ='CM1 & CM2 Metrics'!$C11/'CM1 & CM2 Metrics'!$B11 -> 0 | H11: ='CM1 & CM2 Metrics'!$E11/'CM1 & CM2 Metrics'!$D11 -> 0.59090909 | I11: ='CM1 & CM2 Metrics'!$F11/'CM1 & CM2 Metrics'!$D11 -> 0.40909091
B12: =SUBTOTAL(109,'CM1 & CM2 Metrics'!$B$7:$B$11) -> 151 | C12: =SUBTOTAL(109,'CM1 & CM2 Metrics'!$C$7:$C$11) -> 0 | D12: =SUBTOTAL(109,'CM1 & CM2 Metrics'!$D$7:$D$11) -> 151 | E12: =SUBTOTAL(109,'CM1 & CM2 Metrics'!$E$7:$E$11) -> 98 | F12: =SUBTOTAL(109,'CM1 & CM2 Metrics'!$F$7:$F$11) -> 53 | H12: ='CM1 & CM2 Metrics'!$E$12/'CM1 & CM2 Metrics'!$D$12 -> 0.64900662 | I12: ='CM1 & CM2 Metrics'!$F$12/'CM1 & CM2 Metrics'!$D$12 -> 0.35099338
E13: CM2
A14: Ecole | B14: Insrites | C14: Abandonee # | D14: Presentes # | E14: Admises # | F14: Non Admise # | G14: Abandonee % | H14: Admises % | I14: Non Admise % | J14: Comments
A15: Alsawa | B15: 12 | C15: 0 | D15: 12 | E15: 5 | F15: ='CM1 & CM2 Metrics'!$D15-'CM1 & CM2 Metrics'!$E15 -> 7 | G15: ='CM1 & CM2 Metrics'!$C15/'CM1 & CM2 Metrics'!$B15 -> 0 | H15: ='CM1 & CM2 Metrics'!$E15/'CM1 & CM2 Metrics'!$D15 -> 0.41666667 | I15: ='CM1 & CM2 Metrics'!$F15/'CM1 & CM2 Metrics'!$D15 -> 0.58333333
A16: Dan Bako | B16: 64 | C16: 0 | D16: 64 | E16: 7 | F16: ='CM1 & CM2 Metrics'!$D16-'CM1 & CM2 Metrics'!$E16 -> 57 | G16: ='CM1 & CM2 Metrics'!$C16/'CM1 & CM2 Metrics'!$B16 -> 0 | H16: ='CM1 & CM2 Metrics'!$E16/'CM1 & CM2 Metrics'!$D16 -> 0.109375 | I16: ='CM1 & CM2 Metrics'!$F16/'CM1 & CM2 Metrics'!$D16 -> 0.890625
A17: Dan Gara | B17: 39 | C17: 4 | D17: ='CM1 & CM2 Metrics'!$B17-'CM1 & CM2 Metrics'!$C17 -> 35 | E17: 0 | F17: ='CM1 & CM2 Metrics'!$D17-'CM1 & CM2 Metrics'!$E17 -> 35 | G17: ='CM1 & CM2 Metrics'!$C17/'CM1 & CM2 Metrics'!$B17 -> 0.1025641 | H17: ='CM1 & CM2 Metrics'!$E17/'CM1 & CM2 Metrics'!$D17 -> 0 | I17: ='CM1 & CM2 Metrics'!$F17/'CM1 & CM2 Metrics'!$D17 -> 1
A18: Karambi Sofoua | B18: 10 | C18: 0 | D18: 10 | E18: 5 | F18: ='CM1 & CM2 Metrics'!$D18-'CM1 & CM2 Metrics'!$E18 -> 5 | G18: ='CM1 & CM2 Metrics'!$C18/'CM1 & CM2 Metrics'!$B18 -> 0 | H18: ='CM1 & CM2 Metrics'!$E18/'CM1 & CM2 Metrics'!$D18 -> 0.5 | I18: ='CM1 & CM2 Metrics'!$F18/'CM1 & CM2 Metrics'!$D18 -> 0.5
A19: Mallamaï Salifou | B19: 32 | C19: 2 | D19: ='CM1 & CM2 Metrics'!$B19-'CM1 & CM2 Metrics'!$C19 -> 30 | E19: 3 | F19: ='CM1 & CM2 Metrics'!$D19-'CM1 & CM2 Metrics'!$E19 -> 27 | G19: ='CM1 & CM2 Metrics'!$C19/'CM1 & CM2 Metrics'!$B19 -> 0.0625 | H19: ='CM1 & CM2 Metrics'!$E19/'CM1 & CM2 Metrics'!$D19 -> 0.1 | I19: ='CM1 & CM2 Metrics'!$F19/'CM1 & CM2 Metrics'!$D19 -> 0.9
A20: Mata Milki | B20: 49 | C20: 0 | D20: 49 | E20: 22 | F20: ='CM1 & CM2 Metrics'!$D20-'CM1 & CM2 Metrics'!$E20 -> 27 | G20: ='CM1 & CM2 Metrics'!$C20/'CM1 & CM2 Metrics'!$B20 -> 0 | H20: ='CM1 & CM2 Metrics'!$E20/'CM1 & CM2 Metrics'!$D20 -> 0.44897959 | I20: ='CM1 & CM2 Metrics'!$F20/'CM1 & CM2 Metrics'!$D20 -> 0.55102041
A21: Touzza | B21: 19 | C21: 0 | D21: 19 | E21: 3 | F21: ='CM1 & CM2 Metrics'!$D21-'CM1 & CM2 Metrics'!$E21 -> 16 | G21: ='CM1 & CM2 Metrics'!$C21/'CM1 & CM2 Metrics'!$B21 -> 0 | H21: ='CM1 & CM2 Metrics'!$E21/'CM1 & CM2 Metrics'!$D21 -> 0.15789474 | I21: ='CM1 & CM2 Metrics'!$F21/'CM1 & CM2 Metrics'!$D21 -> 0.84210526
A22: Tsanna | B22: 23 | C22: 8 | D22: ='CM1 & CM2 Metrics'!$B22-'CM1 & CM2 Metrics'!$C22 -> 15 | E22: 1 | F22: ='CM1 & CM2 Metrics'!$D22-'CM1 & CM2 Metrics'!$E22 -> 14 | G22: ='CM1 & CM2 Metrics'!$C22/'CM1 & CM2 Metrics'!$B22 -> 0.34782609 | H22: ='CM1 & CM2 Metrics'!$E22/'CM1 & CM2 Metrics'!$D22 -> 0.066666667 | I22: ='CM1 & CM2 Metrics'!$F22/'CM1 & CM2 Metrics'!$D22 -> 0.93333333
A23: Yan Doto Balla | B23: 48 | C23: 6 | D23: ='CM1 & CM2 Metrics'!$B23-'CM1 & CM2 Metrics'!$C23 -> 42 | E23: 7 | F23: ='CM1 & CM2 Metrics'!$D23-'CM1 & CM2 Metrics'!$E23 -> 35 | G23: ='CM1 & CM2 Metrics'!$C23/'CM1 & CM2 Metrics'!$B23 -> 0.125 | H23: ='CM1 & CM2 Metrics'!$E23/'CM1 & CM2 Metrics'!$D23 -> 0.16666667 | I23: ='CM1 & CM2 Metrics'!$F23/'CM1 & CM2 Metrics'!$D23 -> 0.83333333
A24: Yan Doto Garin Malam | B24: 30 | C24: 0 | D24: 30 | E24: 6 | F24: ='CM1 & CM2 Metrics'!$D24-'CM1 & CM2 Metrics'!$E24 -> 24 | G24: ='CM1 & CM2 Metrics'!$C24/'CM1 & CM2 Metrics'!$B24 -> 0 | H24: ='CM1 & CM2 Metrics'!$E24/'CM1 & CM2 Metrics'!$D24 -> 0.2 | I24: ='CM1 & CM2 Metrics'!$F24/'CM1 & CM2 Metrics'!$D24 -> 0.8
B25: =SUBTOTAL(109,'CM1 & CM2 Metrics'!$B$15:$B$24) -> 326 | C25: =SUBTOTAL(109,'CM1 & CM2 Metrics'!$C$15:$C$24) -> 20 | D25: =SUBTOTAL(109,'CM1 & CM2 Metrics'!$D$15:$D$24) -> 306 | E25: =SUBTOTAL(109,'CM1 & CM2 Metrics'!$E$15:$E$24) -> 59 | F25: =SUBTOTAL(109,'CM1 & CM2 Metrics'!$F$15:$F$24) -> 247 | G25: ='CM1 & CM2 Metrics'!$C$25/'CM1 & CM2 Metrics'!$B$25 -> 0.061349693 | H25: ='CM1 & CM2 Metrics'!$E$25/'CM1 & CM2 Metrics'!$D$25 -> 0.19281046 | I25: ='CM1 & CM2 Metrics'!$F$25/'CM1 & CM2 Metrics'!$D$25 -> 0.80718954
