Workbook

Sheet 1. Base de donnée HILIN MU CM2 
B4: BASE DE DONNEE HILIN MU ( COHORTE 6 )
B5: ANNEE ACADEMIQUE 2023-2024
B6: NIEVAU CM2 | Q6: ENDLINE
A7: Ecole | B7: Commune | C7: Nom et prénom de la fille | D7: Nom de Titulaire de la fille au club | E7: Date et lieu de Naissance | F7: Nom de Titulaire de la Fille au club | G7: Annee d'inscription au programme2 | H7: Code de l'école | I7: Numéro HM de la fille | J7: Identifiant Unique | K7: Total des filles | L7: Situation des Filles Fin d'année 2022-2023 | M7: Commetaire sur la situation des Filles 2023-2024 | N7: Commentaire | O7: Mathématique/20 | P7: Français /20 | Q7: Moyenne générale/20 | R7: Mathématique /20 | S7: Français /202 | T7: Moyenne générale2 | U7: Moyenne générale3
A8: Katare 2 | B8: Tibiri/Gobir | C8: Nana Aicha Tsalha | D8: Tsalha Issoufou | E8: 31/12/2011 à Katare | F8: Mme Moussa Mariama | G8: 2023 | H8: 3 | I8: 2 | J8: ='1. Base de donnée HILIN MU CM2 '!$G8&"-"&'1. Base de donnée HILIN MU CM2 '!$H8&"-"&'1. Base de donnée HILIN MU CM2 '!$I8 -> 2023-3-2 | K8: 1 | L8: Passe au CM2 | O8: 3.5 | P8: 6 | Q8: =SUM('1. Base de donnée HILIN MU CM2 '!$O8+'1. Base de donnée HILIN MU CM2 '!$P8)/2 -> 4.75 | R8: 15 | S8: 19 | T8: =('1. Base de donnée HILIN MU CM2 '!$R8+'1. Base de donnée HILIN MU CM2 '!$S8)/2 -> 17
A9: Katare 2 | B9: Tibiri/Gobir | C9: Zainab Hakilou | D9: Hakilou | E9: 31/12/2011 à katare | F9: Mme Ibrahim Nana | G9: 2023 | H9: 3 | I9: 3 | J9: ='1. Base de donnée HILIN MU CM2 '!$G9&"-"&'1. Base de donnée HILIN MU CM2 '!$H9&"-"&'1. Base de donnée HILIN MU CM2 '!$I9 -> 2023-3-3 | K9: =SUM(K8+1) -> 2 | L9: Passe au CM2 | O9: 6 | P9: 6.5 | Q9: =SUM('1. Base de donnée HILIN MU CM2 '!$O9+'1. Base de donnée HILIN MU CM2 '!$P9)/2 -> 6.25 | R9: 19 | S9: 18.25 | T9: =('1. Base de donnée HILIN MU CM2 '!$R9+'1. Base de donnée HILIN MU CM2 '!$S9)/2 -> 18.625
A10: Katare 2 | B10: Tibiri/Gobir | C10: Mariam Chaibou | D10: Chaibou | E10: 31/12/2011 à katare | F10: Mme Ibrahim Nana | G10: 2023 | H10: 3 | I10: 4 | J10: ='1. Base de donnée HILIN MU CM2 '!$G10&"-"&'1. Base de donnée HILIN MU CM2 '!$H10&"-"&'1. Base de donnée HILIN MU CM2 '!$I10 -> 2023-3-4 | K10: =SUM(K9+1) -> 3 | L10: Passe au CM2 | O10: 3 | P10: 3.5 | Q10: =SUM('1. Base de donnée HILIN MU CM2 '!$O10+'1. Base de donnée HILIN MU CM2 '!$P10)/2 -> 3.25 | R10: 18 | S10: 15 | T10: =('1. Base de donnée HILIN MU CM2 '!$R10+'1. Base de donnée HILIN MU CM2 '!$S10)/2 -> 16.5
A11: Katare 2 | B11: Tibiri/Gobir | C11: Samira Elhadji tsalha | D11: Elhadji Tsalha Issoufou | E11: 31/12/2011 à katare | F11: Mme Ibrahim Nana | G11: 2023 | H11: 3 | I11: 5 | J11: ='1. Base de donnée HILIN MU CM2 '!$G11&"-"&'1. Base de donnée HILIN MU CM2 '!$H11&"-"&'1. Base de donnée HILIN MU CM2 '!$I11 -> 2023-3-5 | K11: =SUM(K10+1) -> 4 | L11: Passe au CM2 | O11: 2.5 | P11: 1.25 | Q11: =SUM('1. Base de donnée HILIN MU CM2 '!$O11+'1. Base de donnée HILIN MU CM2 '!$P11)/2 -> 1.875 | R11: 14.5 | S11: 17.5 | T11: =('1. Base de donnée HILIN MU CM2 '!$R11+'1. Base de donnée HILIN MU CM2 '!$S11)/2 -> 16
A12: Katare 2 | B12: Tibiri/Gobir | C12: Aliya Roufai | D12: Roufai | E12: 31/12/2011 à katare | F12: Mme Ibrahim Nana | G12: 2023 | H12: 3 | I12: 6 | J12: ='1. Base de donnée HILIN MU CM2 '!$G12&"-"&'1. Base de donnée HILIN MU CM2 '!$H12&"-"&'1. Base de donnée HILIN MU CM2 '!$I12 -> 2023-3-6 | K12: =SUM(K11+1) -> 5 | L12: Passe au CM2 | O12: 6.25 | P12: 1 | Q12: =SUM('1. Base de donnée HILIN MU CM2 '!$O12+'1. Base de donnée HILIN MU CM2 '!$P12)/2 -> 3.625 | R12: 16 | S12: 14.5 | T12: =('1. Base de donnée HILIN MU CM2 '!$R12+'1. Base de donnée HILIN MU CM2 '!$S12)/2 -> 15.25
A13: Katare 2 | B13: Tibiri/Gobir | C13: Azima Harouna | D13: Harouna Ousseini | E13: 31/12/2011 à katare | F13: Mme Moussa Mariama | G13: 2023 | H13: 3 | I13: 7 | J13: ='1. Base de donnée HILIN MU CM2 '!$G13&"-"&'1. Base de donnée HILIN MU CM2 '!$H13&"-"&'1. Base de donnée HILIN MU CM2 '!$I13 -> 2023-3-7 | K13: =SUM(K12+1) -> 6 | L13: Passe au CM2 | O13: 3 | P13: 4.5 | Q13: =SUM('1. Base de donnée HILIN MU CM2 '!$O13+'1. Base de donnée HILIN MU CM2 '!$P13)/2 -> 3.75 | R13: 13 | S13: 16 | T13: =('1. Base de donnée HILIN MU CM2 '!$R13+'1. Base de donnée HILIN MU CM2 '!$S13)/2 -> 14.5
A14: Katare 2 | B14: Tibiri/Gobir | C14: Fatiha Amadou | D14: Amadou Laouali | E14: 31/12/2011 à katare | F14: Mme Ibrahim Nana | G14: 2023 | H14: 3 | I14: 8 | J14: ='1. Base de donnée HILIN MU CM2 '!$G14&"-"&'1. Base de donnée HILIN MU CM2 '!$H14&"-"&'1. Base de donnée HILIN MU CM2 '!$I14 -> 2023-3-8 | K14: =SUM(K13+1) -> 7 | L14: Passe au CM2 | O14: 6.5 | P14: 8 | Q14: =SUM('1. Base de donnée HILIN MU CM2 '!$O14+'1. Base de donnée HILIN MU CM2 '!$P14)/2 -> 7.25 | R14: 18.25 | S14: 15 | T14: =('1. Base de donnée HILIN MU CM2 '!$R14+'1. Base de donnée HILIN MU CM2 '!$S14)/2 -> 16.625
A15: Katare 2 | B15: Tibiri/Gobir | C15: Nana Nahaitou Hamissou | D15: Hamissou abdou | E15: 31/12/2011 à katare | F15: Mme Moussa Mariama | G15: 2023 | H15: 3 | I15: 9 | J15: ='1. Base de donnée HILIN MU CM2 '!$G15&"-"&'1. Base de donnée HILIN MU CM2 '!$H15&"-"&'1. Base de donnée HILIN MU CM2 '!$I15 -> 2023-3-9 | K15: =SUM(K14+1) -> 8 | L15: Passe au CM2 | O15: 2.5 | P15: 5 | Q15: =SUM('1. Base de donnée HILIN MU CM2 '!$O15+'1. Base de donnée HILIN MU CM2 '!$P15)/2 -> 3.75 | R15: 17 | S15: 18 | T15: =('1. Base de donnée HILIN MU CM2 '!$R15+'1. Base de donnée HILIN MU CM2 '!$S15)/2 -> 17.5
A16: Katare 2 | B16: Tibiri/Gobir | C16: Nana Kaoussar Sahailou | D16: Sahailou tsalha | E16: 31/12/2011 à katare | F16: Mme Moussa Mariama | G16: 2023 | H16: 3 | I16: 10 | J16: ='1. Base de donnée HILIN MU CM2 '!$G16&"-"&'1. Base de donnée HILIN MU CM2 '!$H16&"-"&'1. Base de donnée HILIN MU CM2 '!$I16 -> 2023-3-10 | K16: =SUM(K15+1) -> 9 | L16: Passe au CM2 | O16: 8.5 | P16: 8.75 | Q16: =SUM('1. Base de donnée HILIN MU CM2 '!$O16+'1. Base de donnée HILIN MU CM2 '!$P16)/2 -> 8.625 | R16: 19 | S16: 15.75 | T16: =('1. Base de donnée HILIN MU CM2 '!$R16+'1. Base de donnée HILIN MU CM2 '!$S16)/2 -> 17.375
A17: Katare 2 | B17: Tibiri/Gobir | C17: Sabila Hamza Issa | D17: Hamza Issa | E17: 31/12/2011 à katare | F17: Mme Moussa Mariama | G17: 2023 | H17: 3 | I17: 11 | J17: ='1. Base de donnée HILIN MU CM2 '!$G17&"-"&'1. Base de donnée HILIN MU CM2 '!$H17&"-"&'1. Base de donnée HILIN MU CM2 '!$I17 -> 2023-3-11 | K17: =SUM(K16+1) -> 10 | L17: Passe au CM2 | O17: 8 | P17: 9 | Q17: =SUM('1. Base de donnée HILIN MU CM2 '!$O17+'1. Base de donnée HILIN MU CM2 '!$P17)/2 -> 8.5 | R17: 18 | S17: 17.75 | T17: =('1. Base de donnée HILIN MU CM2 '!$R17+'1. Base de donnée HILIN MU CM2 '!$S17)/2 -> 17.875
A18: Katare 2 | B18: Tibiri/Gobir | C18: Amina Ousmane | D18: Ousmane | E18: 31/12/2011 à katare | F18: Mme Ibrahim Nana | G18: 2023 | H18: 3 | I18: 12 | J18: ='1. Base de donnée HILIN MU CM2 '!$G18&"-"&'1. Base de donnée HILIN MU CM2 '!$H18&"-"&'1. Base de donnée HILIN MU CM2 '!$I18 -> 2023-3-12 | K18: =SUM(K17+1) -> 11 | L18: Passe au CM2 | O18: 2.5 | P18: 5.25 | Q18: =SUM('1. Base de donnée HILIN MU CM2 '!$O18+'1. Base de donnée HILIN MU CM2 '!$P18)/2 -> 3.875 | R18: 16 | S18: 15.5 | T18: =('1. Base de donnée HILIN MU CM2 '!$R18+'1. Base de donnée HILIN MU CM2 '!$S18)/2 -> 15.75
A19: Katare 2 | B19: Tibiri/Gobir | C19: Amatoulaye Ibrahim | D19: Ibrahim | E19: 31/12/2011 à katare | F19: Mme Ibrahim Nana | G19: 2023 | H19: 3 | I19: 13 | J19: ='1. Base de donnée HILIN MU CM2 '!$G19&"-"&'1. Base de donnée HILIN MU CM2 '!$H19&"-"&'1. Base de donnée HILIN MU CM2 '!$I19 -> 2023-3-13 | K19: =SUM(K18+1) -> 12 | L19: Passe au CM2 | O19: 1.25 | P19: 0.5 | Q19: =SUM('1. Base de donnée HILIN MU CM2 '!$O19+'1. Base de donnée HILIN MU CM2 '!$P19)/2 -> 0.875 | R19: 16 | S19: 16.5 | T19: =('1. Base de donnée HILIN MU CM2 '!$R19+'1. Base de donnée HILIN MU CM2 '!$S19)/2 -> 16.25
A20: Katare 2 | B20: Tibiri/Gobir | C20: Fati Issia | D20: Issia | E20: 31/12/2011 à katare | F20: Mme Moussa Mariama | G20: 2023 | H20: 3 | I20: 14 | J20: ='1. Base de donnée HILIN MU CM2 '!$G20&"-"&'1. Base de donnée HILIN MU CM2 '!$H20&"-"&'1. Base de donnée HILIN MU CM2 '!$I20 -> 2023-3-14 | K20: =SUM(K19+1) -> 13 | L20: Passe au CM2 | O20: 7 | P20: 10.75 | Q20: =SUM('1. Base de donnée HILIN MU CM2 '!$O20+'1. Base de donnée HILIN MU CM2 '!$P20)/2 -> 8.875 | R20: 18.25 | S20: 17 | T20: =('1. Base de donnée HILIN MU CM2 '!$R20+'1. Base de donnée HILIN MU CM2 '!$S20)/2 -> 17.625
... A68: Louloubi | B68: Sae Saboua | C68: Nafissa Adamou | D68: Adamou Abdou | E68: 01/01/2010 à louloubi | F68: Mme Ramatou Ibrahim Bawa | G68: 2023 | H68: 89 | I68: 56 | J68: ='1. Base de donnée HILIN MU CM2 '!$G68&"-"&'1. Base de donnée HILIN MU CM2 '!$H68&"-"&'1. Base de donnée HILIN MU CM2 '!$I68 -> 2023-89-56 | K68: =SUM(K67+1) -> 61 | L68: Passe au CM2 | O68: 6 | P68: 7.25 | Q68: =SUM('1. Base de donnée HILIN MU CM2 '!$O68+'1. Base de donnée HILIN MU CM2 '!$P68)/2 -> 6.625 | R68: 12 | S68: 11 | T68: =('1. Base de donnée HILIN MU CM2 '!$R68+'1. Base de donnée HILIN MU CM2 '!$S68)/2 -> 11.5
A69: Louloubi | B69: Sae Saboua | C69: Nousseiba Sadou | D69: Saadou Bala | E69: 01/01/2010 à louloubi | F69: Mme Ramatou Ibrahim Bawa | G69: 2023 | H69: 89 | I69: 57 | J69: ='1. Base de donnée HILIN MU CM2 '!$G69&"-"&'1. Base de donnée HILIN MU CM2 '!$H69&"-"&'1. Base de donnée HILIN MU CM2 '!$I69 -> 2023-89-57 | K69: =SUM(K68+1) -> 62 | L69: Passe au CM2 | O69: transferée | P69: 4.5
A70: Louloubi | B70: Sae Saboua | C70: Loubabatou Yacouba | D70: Yacouba | E70: 01/01/2010 à louloubi | F70: Mme Ramatou Ibrahim Bawa | G70: 2023 | H70: 89 | I70: 58 | J70: ='1. Base de donnée HILIN MU CM2 '!$G70&"-"&'1. Base de donnée HILIN MU CM2 '!$H70&"-"&'1. Base de donnée HILIN MU CM2 '!$I70 -> 2023-89-58 | K70: =SUM(K69+1) -> 63 | L70: Passe au CM2 | O70: 1.5 | P70: 4.75 | Q70: =SUM('1. Base de donnée HILIN MU CM2 '!$O70+'1. Base de donnée HILIN MU CM2 '!$P70)/2 -> 3.125 | R70: 8.5 | S70: 12 | T70: =('1. Base de donnée HILIN MU CM2 '!$R70+'1. Base de donnée HILIN MU CM2 '!$S70)/2 -> 10.25
A71: Louloubi | B71: Sae Saboua | C71: Azima Alassan | D71: Alassan Ibrahim | E71: 01/01/2010 à louloubi | F71: Mme Hamisou Saybatou | G71: 2022 | H71: 89 | I71: 1 | J71: ='1. Base de donnée HILIN MU CM2 '!$G71&"-"&'1. Base de donnée HILIN MU CM2 '!$H71&"-"&'1. Base de donnée HILIN MU CM2 '!$I71 -> 2022-89-1 | K71: =SUM(K70+1) -> 64 | L71: Passe au CM2 | O71: 1.5 | P71: 5 | Q71: =SUM('1. Base de donnée HILIN MU CM2 '!$O71+'1. Base de donnée HILIN MU CM2 '!$P71)/2 -> 3.25 | R71: 14 | S71: 11.5 | T71: =('1. Base de donnée HILIN MU CM2 '!$R71+'1. Base de donnée HILIN MU CM2 '!$S71)/2 -> 12.75
A72: Louloubi | B72: Sae Saboua | C72: Nassaiba Yacoubou | D72: Yacoubou Ousmane | E72: 01/01/2010 à louloubi | F72: Mme Hamisou Saybatou | G72: 2022 | H72: 89 | I72: 8 | J72: ='1. Base de donnée HILIN MU CM2 '!$G72&"-"&'1. Base de donnée HILIN MU CM2 '!$H72&"-"&'1. Base de donnée HILIN MU CM2 '!$I72 -> 2022-89-8 | K72: =SUM(K71+1) -> 65 | L72: Passe au CM2 | O72: transferée
A73: Louloubi | B73: Sae Saboua | C73: Napissa Oumarou | D73: Oumarou Yacouba | E73: 01/01/2010 à louloubi | F73: Mme Hamisou Saybatou | G73: 2022 | H73: 89 | I73: 9 | J73: ='1. Base de donnée HILIN MU CM2 '!$G73&"-"&'1. Base de donnée HILIN MU CM2 '!$H73&"-"&'1. Base de donnée HILIN MU CM2 '!$I73 -> 2022-89-9 | K73: =SUM(K72+1) -> 66 | L73: Passe au CM2 | O73: 3 | P73: 3 | Q73: =SUM('1. Base de donnée HILIN MU CM2 '!$O73+'1. Base de donnée HILIN MU CM2 '!$P73)/2 -> 3 | R73: 11 | S73: 12 | T73: =('1. Base de donnée HILIN MU CM2 '!$R73+'1. Base de donnée HILIN MU CM2 '!$S73)/2 -> 11.5
A74: Louloubi | B74: Sae Saboua | C74: Habiba Aliou | D74: Aliou Yahaya | E74: 01/01/2010 à louloubi | F74: Mme Hamisou Saybatou | G74: 2022 | H74: 89 | I74: 14 | J74: ='1. Base de donnée HILIN MU CM2 '!$G74&"-"&'1. Base de donnée HILIN MU CM2 '!$H74&"-"&'1. Base de donnée HILIN MU CM2 '!$I74 -> 2022-89-14 | K74: =SUM(K73+1) -> 67 | L74: Passe au CM2 | O74: 3.5 | P74: 6 | Q74: =SUM('1. Base de donnée HILIN MU CM2 '!$O74+'1. Base de donnée HILIN MU CM2 '!$P74)/2 -> 4.75 | R74: 14 | S74: 16.5 | T74: =('1. Base de donnée HILIN MU CM2 '!$R74+'1. Base de donnée HILIN MU CM2 '!$S74)/2 -> 15.25
A75: Louloubi | B75: Sae Saboua | C75: Azima Idi | D75: Idi | E75: 01/01/2010 à louloubi | F75: Mme Ramatou Ibrahim Bawa | G75: 2024 | H75: 89 | I75: 930 | J75: ='1. Base de donnée HILIN MU CM2 '!$G75&"-"&'1. Base de donnée HILIN MU CM2 '!$H75&"-"&'1. Base de donnée HILIN MU CM2 '!$I75 -> 2024-89-930 | K75: =SUM(K74+1) -> 68 | L75: Passe au CM2 | O75: 5 | P75: 4 | Q75: =SUM('1. Base de donnée HILIN MU CM2 '!$O75+'1. Base de donnée HILIN MU CM2 '!$P75)/2 -> 4.5 | R75: 14 | S75: 11.5 | T75: =('1. Base de donnée HILIN MU CM2 '!$R75+'1. Base de donnée HILIN MU CM2 '!$S75)/2 -> 12.75
A76: Louloubi | B76: Sae Saboua | C76: Aicha Laouali | D76: Laouali | E76: 01/01/2010 à louloubi | F76: Mme Ramatou Ibrahim Bawa | G76: 2024 | H76: 89 | I76: 931 | J76: ='1. Base de donnée HILIN MU CM2 '!$G76&"-"&'1. Base de donnée HILIN MU CM2 '!$H76&"-"&'1. Base de donnée HILIN MU CM2 '!$I76 -> 2024-89-931 | K76: =SUM(K75+1) -> 69 | L76: Passe au CM2 | O76: 6.5 | P76: 8 | Q76: =SUM('1. Base de donnée HILIN MU CM2 '!$O76+'1. Base de donnée HILIN MU CM2 '!$P76)/2 -> 7.25 | R76: 17 | S76: 13.5 | T76: =('1. Base de donnée HILIN MU CM2 '!$R76+'1. Base de donnée HILIN MU CM2 '!$S76)/2 -> 15.25
A77: Louloubi | B77: Sae Saboua | C77: Farida Saadou | D77: Saadou | E77: 01/01/2010 à louloubi | F77: Mme Hamisou Saybatou | G77: 2024 | H77: 89 | I77: 932 | J77: ='1. Base de donnée HILIN MU CM2 '!$G77&"-"&'1. Base de donnée HILIN MU CM2 '!$H77&"-"&'1. Base de donnée HILIN MU CM2 '!$I77 -> 2024-89-932 | K77: =SUM(K76+1) -> 70 | L77: Passe au CM2 | O77: 6 | P77: 7 | Q77: =SUM('1. Base de donnée HILIN MU CM2 '!$O77+'1. Base de donnée HILIN MU CM2 '!$P77)/2 -> 6.5 | R77: 18 | S77: 14 | T77: =('1. Base de donnée HILIN MU CM2 '!$R77+'1. Base de donnée HILIN MU CM2 '!$S77)/2 -> 16
A78: Louloubi | B78: Sae Saboua | C78: Fatchima Ibrahim | D78: Ibrahim | E78: 01/01/2010 à louloubi | F78: Mme Ramatou Ibrahim Bawa | G78: 2024 | H78: 89 | I78: 933 | J78: ='1. Base de donnée HILIN MU CM2 '!$G78&"-"&'1. Base de donnée HILIN MU CM2 '!$H78&"-"&'1. Base de donnée HILIN MU CM2 '!$I78 -> 2024-89-933 | K78: =SUM(K77+1) -> 71 | L78: Passe au CM2 | O78: 5 | P78: 6.5 | Q78: =SUM('1. Base de donnée HILIN MU CM2 '!$O78+'1. Base de donnée HILIN MU CM2 '!$P78)/2 -> 5.75 | R78: 17 | S78: 14 | T78: =('1. Base de donnée HILIN MU CM2 '!$R78+'1. Base de donnée HILIN MU CM2 '!$S78)/2 -> 15.5
A79: Louloubi | B79: Sae Saboua | C79: Ramatou Abdoul Karim | D79: Abdoul Karim | E79: 01/01/2010 à louloubi | F79: Mme Hamisou Saybatou | G79: 2024 | H79: 89 | I79: 934 | J79: ='1. Base de donnée HILIN MU CM2 '!$G79&"-"&'1. Base de donnée HILIN MU CM2 '!$H79&"-"&'1. Base de donnée HILIN MU CM2 '!$I79 -> 2024-89-934 | K79: =SUM(K78+1) -> 72 | L79: Passe au CM2 | O79: 4 | P79: 4.25 | Q79: =SUM('1. Base de donnée HILIN MU CM2 '!$O79+'1. Base de donnée HILIN MU CM2 '!$P79)/2 -> 4.125 | R79: 19.5 | S79: 20 | T79: =('1. Base de donnée HILIN MU CM2 '!$R79+'1. Base de donnée HILIN MU CM2 '!$S79)/2 -> 19.75
A80: Louloubi | B80: Sae Saboua | C80: Ramatou Oumarou | D80: Oumarou | E80: 01/01/2010 à louloubi | F80: Mme Ramatou Ibrahim Bawa | G80: 2024 | H80: 89 | I80: 935 | J80: ='1. Base de donnée HILIN MU CM2 '!$G80&"-"&'1. Base de donnée HILIN MU CM2 '!$H80&"-"&'1. Base de donnée HILIN MU CM2 '!$I80 -> 2024-89-935 | K80: =SUM(K79+1) -> 73 | L80: Passe au CM2 | O80: 4 | P80: 5.5 | Q80: =SUM('1. Base de donnée HILIN MU CM2 '!$O80+'1. Base de donnée HILIN MU CM2 '!$P80)/2 -> 4.75 | R80: 16.5 | S80: 16.5 | T80: =('1. Base de donnée HILIN MU CM2 '!$R80+'1. Base de donnée HILIN MU CM2 '!$S80)/2 -> 16.5
A81: Louloubi | B81: Sae Saboua | C81: Ramatou Yahaya | D81: Yahaya | E81: 01/01/2010 à louloubi | F81: Mme Hamisou Saybatou | G81: 2024 | H81: 89 | I81: 936 | J81: ='1. Base de donnée HILIN MU CM2 '!$G81&"-"&'1. Base de donnée HILIN MU CM2 '!$H81&"-"&'1. Base de donnée HILIN MU CM2 '!$I81 -> 2024-89-936 | K81: =SUM(K80+1) -> 74 | L81: Passe au CM2 | O81: 7.5 | P81: 7 | Q81: =SUM('1. Base de donnée HILIN MU CM2 '!$O81+'1. Base de donnée HILIN MU CM2 '!$P81)/2 -> 7.25 | R81: 16.5 | S81: 16.5 | T81: =('1. Base de donnée HILIN MU CM2 '!$R81+'1. Base de donnée HILIN MU CM2 '!$S81)/2 -> 16.5
A82: Soura 3 | B82: Tibiri/Gobir | C82: Shamsia Laouali | D82: Laouali | E82: 01/01/2012 à Soura | F82: Mme Boubacar Fatchouma | G82: 2023 | H82: 2 | I82: 59 | J82: ='1. Base de donnée HILIN MU CM2 '!$G82&"-"&'1. Base de donnée HILIN MU CM2 '!$H82&"-"&'1. Base de donnée HILIN MU CM2 '!$I82 -> 2023-2-59 | K82: =SUM(K81+1) -> 75 | L82: Passe au CM2 | O82: 12 | P82: 1.5 | Q82: =SUM('1. Base de donnée HILIN MU CM2 '!$O82+'1. Base de donnée HILIN MU CM2 '!$P82)/2 -> 6.75 | R82: 16 | S82: 17 | T82: =('1. Base de donnée HILIN MU CM2 '!$R82+'1. Base de donnée HILIN MU CM2 '!$S82)/2 -> 16.5
A83: Soura 3 | B83: Tibiri/Gobir | C83: Firdaoussi Sanoussi | D83: Sanoussi | E83: 01/01/2012 à Soura | F83: Mme Boubacar Fatchouma | G83: 2023 | H83: 2 | I83: 60 | J83: ='1. Base de donnée HILIN MU CM2 '!$G83&"-"&'1. Base de donnée HILIN MU CM2 '!$H83&"-"&'1. Base de donnée HILIN MU CM2 '!$I83 -> 2023-2-60 | K83: =SUM(K82+1) -> 76 | L83: Passe au CM2 | O83: 8 | P83: 6 | Q83: =SUM('1. Base de donnée HILIN MU CM2 '!$O83+'1. Base de donnée HILIN MU CM2 '!$P83)/2 -> 7 | R83: 16 | S83: 15.5 | T83: =('1. Base de donnée HILIN MU CM2 '!$R83+'1. Base de donnée HILIN MU CM2 '!$S83)/2 -> 15.75
A84: Soura 3 | B84: Tibiri/Gobir | C84: Zainab Sani | D84: Sani Chaibou | E84: 01/01/2012 à Soura | F84: Mme Boubacar Fatchouma | G84: 2023 | H84: 2 | I84: 61 | J84: ='1. Base de donnée HILIN MU CM2 '!$G84&"-"&'1. Base de donnée HILIN MU CM2 '!$H84&"-"&'1. Base de donnée HILIN MU CM2 '!$I84 -> 2023-2-61 | K84: =SUM(K83+1) -> 77 | L84: Passe au CM2 | O84: 4.5 | P84: 7 | Q84: =SUM('1. Base de donnée HILIN MU CM2 '!$O84+'1. Base de donnée HILIN MU CM2 '!$P84)/2 -> 5.75 | R84: 17.75 | S84: 18.25 | T84: =('1. Base de donnée HILIN MU CM2 '!$R84+'1. Base de donnée HILIN MU CM2 '!$S84)/2 -> 18
... A93: Soura 3 | B93: Tibiri/Gobir | C93: Souraya Salissou | D93: Salissou Amani | E93: 01/01/2012 à Soura | F93: Mme Boubacar Fatchouma | G93: 2023 | H93: 2 | I93: 71 | J93: ='1. Base de donnée HILIN MU CM2 '!$G93&"-"&'1. Base de donnée HILIN MU CM2 '!$H93&"-"&'1. Base de donnée HILIN MU CM2 '!$I93 -> 2023-2-71 | K93: =SUM(K92+1) -> 86 | L93: Passe au CM2 | O93: 12.5 | P93: 6.5 | Q93: =SUM('1. Base de donnée HILIN MU CM2 '!$O93+'1. Base de donnée HILIN MU CM2 '!$P93)/2 -> 9.5 | R93: 17 | S93: 17 | T93: =('1. Base de donnée HILIN MU CM2 '!$R93+'1. Base de donnée HILIN MU CM2 '!$S93)/2 -> 17
A94: Soura 3 | B94: Tibiri/Gobir | C94: Chamsiya Boureima | D94: Boureima | E94: 01/01/2011 à Soura | G94: 2023 | H94: 2 | I94: 889 | J94: ='1. Base de donnée HILIN MU CM2 '!$G94&"-"&'1. Base de donnée HILIN MU CM2 '!$H94&"-"&'1. Base de donnée HILIN MU CM2 '!$I94 -> 2023-2-889 | K94: =SUM(K93+1) -> 87 | L94: Passe au CM2 | M94: Abandon | N94: Abandon | Q94: =SUM('1. Base de donnée HILIN MU CM2 '!$O94+'1. Base de donnée HILIN MU CM2 '!$P94)/2 -> 0 | T94: =('1. Base de donnée HILIN MU CM2 '!$R94+'1. Base de donnée HILIN MU CM2 '!$S94)/2 -> 0 | U94: transferée
A95: Soura 3 | B95: Tibiri/Gobir | C95: Rissala Salissou | D95: Salissou | E95: 01/01/2011 à Soura | F95: Mme Boubacar Fatchouma | G95: 2023 | H95: 2 | I95: 891 | J95: ='1. Base de donnée HILIN MU CM2 '!$G95&"-"&'1. Base de donnée HILIN MU CM2 '!$H95&"-"&'1. Base de donnée HILIN MU CM2 '!$I95 -> 2023-2-891 | K95: =SUM(K94+1) -> 88 | L95: Passe au CM2 | O95: 11 | P95: 3.5 | Q95: =SUM('1. Base de donnée HILIN MU CM2 '!$O95+'1. Base de donnée HILIN MU CM2 '!$P95)/2 -> 7.25 | R95: 15 | S95: 13.5 | T95: =('1. Base de donnée HILIN MU CM2 '!$R95+'1. Base de donnée HILIN MU CM2 '!$S95)/2 -> 14.25
A96: Soura 3 | B96: Tibiri/Gobir | C96: Soumaya Nassirou | D96: Nassirou | E96: 01/01/2011 à Soura | F96: Mme Boubacar Fatchouma | G96: 2023 | H96: 2 | I96: 893 | J96: ='1. Base de donnée HILIN MU CM2 '!$G96&"-"&'1. Base de donnée HILIN MU CM2 '!$H96&"-"&'1. Base de donnée HILIN MU CM2 '!$I96 -> 2023-2-893 | K96: =SUM(K95+1) -> 89 | L96: Passe au CM2 | O96: 9.5 | P96: 6 | Q96: =SUM('1. Base de donnée HILIN MU CM2 '!$O96+'1. Base de donnée HILIN MU CM2 '!$P96)/2 -> 7.75 | R96: 15 | S96: 13 | T96: =('1. Base de donnée HILIN MU CM2 '!$R96+'1. Base de donnée HILIN MU CM2 '!$S96)/2 -> 14
A97: Soura 3 | B97: Tibiri/Gobir | C97: Soumaya Issoufou | D97: Issoufou | E97: 01/01/2011 à Soura | F97: Mme Boubacar Fatchouma | G97: 2023 | H97: 2 | I97: 894 | J97: ='1. Base de donnée HILIN MU CM2 '!$G97&"-"&'1. Base de donnée HILIN MU CM2 '!$H97&"-"&'1. Base de donnée HILIN MU CM2 '!$I97 -> 2023-2-894 | K97: =SUM(K96+1) -> 90 | L97: Passe au CM2 | O97: 11.5 | P97: 10.5 | Q97: =SUM('1. Base de donnée HILIN MU CM2 '!$O97+'1. Base de donnée HILIN MU CM2 '!$P97)/2 -> 11 | R97: 18 | S97: 18.5 | T97: =('1. Base de donnée HILIN MU CM2 '!$R97+'1. Base de donnée HILIN MU CM2 '!$S97)/2 -> 18.25
A98: Takalmaoua 1 | B98: Djiratawa | C98: Karima Baraou | D98: Baraou | E98: 01/01/2012 àTakalmaoua | F98: Mme Amadou Aminatou | G98: 2023 | H98: 36 | I98: 72 | J98: ='1. Base de donnée HILIN MU CM2 '!$G98&"-"&'1. Base de donnée HILIN MU CM2 '!$H98&"-"&'1. Base de donnée HILIN MU CM2 '!$I98 -> 2023-36-72 | K98: =SUM(K97+1) -> 91 | L98: Passe au CM2 | O98: 0.5 | P98: 3 | Q98: =SUM('1. Base de donnée HILIN MU CM2 '!$O98+'1. Base de donnée HILIN MU CM2 '!$P98)/2 -> 1.75 | R98: 16 | S98: 12.5 | T98: =('1. Base de donnée HILIN MU CM2 '!$R98+'1. Base de donnée HILIN MU CM2 '!$S98)/2 -> 14.25
...
