Workbook

Sheet Groupe Intervention 
A1: Base de donnée du programme Hilin Mu
A2: Niveau :CM2
A3: Année :2022-2023
K4: Pré-Test | N4: Post-Test
A5: Ecole | B5: Nom et Prénom | C5: Date et lieu de naissance | D5: Nom et prénom du père | E5: Nom de la commune | F5: Nombre des filles | G5: Annee d'inscription au programme | H5: Code des écoles | I5: Numero HM de la fille | J5: Identifiant Unique | K5: Français /20 | L5: Mathématique/20 | M5: Moyenne Génerale /20 | N5: Français 20 | O5: Mathématique /2O | P5: Moyenne Génerale /20 | Q5: 1ère composition/10 | R5: 2è composition/10 | S5: 3è composition/10 | T5: Moyenne générale | U5: Commentaire | V5: Situation (fin d'annee scolaire 2022-2023)
A6: Louloubi | B6: Azima Alassan | C6: 30/12/2009 à Louloubi | D6: Alassan Ibrahim | E6: Sae Saboua | F6: 1 | G6: 2022 | H6: 1 | I6: 1 | J6: =[1]!Tableau2[[#This Row],[Annee d''inscription au programme]]&"-"&[1]!Tableau2[[#This Row],[Code d''ecole]]&"-"&[1]!Tableau2[[#This Row],[Numero HM de la fille]] -> #ERROR! | K6: 2.5 | L6: 3.5 | M6: =SUM(K6+L6)/2 -> 3 | N6: 11.5 | O6: 16 | P6: =SUM(N6+O6)/2 -> 13.75
A7: Louloubi | B7: Azima Idi | C7: 31/12/2010 à Louloubi | D7: Idi Daouda | E7: Sae Saboua | F7: 2 | G7: 2022 | H7: 1 | I7: 2 | J7: =[1]!Tableau2[[#This Row],[Annee d''inscription au programme]]&"-"&[1]!Tableau2[[#This Row],[Code d''ecole]]&"-"&[1]!Tableau2[[#This Row],[Numero HM de la fille]] -> #ERROR! | K7: 7 | L7: 4.5 | M7: =SUM(K7+L7)/2 -> 5.75 | N7: 14.5 | O7: 12.5 | P7: =SUM(N7+O7)/2 -> 13.5
A8: Louloubi | B8: Aicha Salissou | C8: 31/12/2010 0 Louloubi | D8: Salissou Soulé | E8: Sae Saboua | F8: 3 | G8: 2022 | H8: 1 | I8: 3 | J8: =[1]!Tableau2[[#This Row],[Annee d''inscription au programme]]&"-"&[1]!Tableau2[[#This Row],[Code d''ecole]]&"-"&[1]!Tableau2[[#This Row],[Numero HM de la fille]] -> #ERROR! | K8: 7.5 | L8: 7 | M8: =SUM(K8+L8)/2 -> 7.25 | N8: 16 | O8: 12.5 | P8: =SUM(N8+O8)/2 -> 14.25
A9: Louloubi | B9: Barira Moussa | C9: 01/01/2010 à Louloubi | D9: Moussa Labo | E9: Sae Saboua | F9: 4 | G9: 2022 | H9: 1 | I9: 4 | J9: =[1]!Tableau2[[#This Row],[Annee d''inscription au programme]]&"-"&[1]!Tableau2[[#This Row],[Code d''ecole]]&"-"&[1]!Tableau2[[#This Row],[Numero HM de la fille]] -> #ERROR! | K9: 12 | L9: 5.5 | M9: =SUM(K9+L9)/2 -> 8.75 | N9: 15.75 | O9: 16 | P9: =SUM(N9+O9)/2 -> 15.875
A10: Louloubi | B10: Bassira Haladou | C10: 16/02/2009 à Louloubi | D10: Haladou Ousmane | E10: Sae Saboua | F10: 5 | G10: 2022 | H10: 1 | I10: 5 | J10: =[1]!Tableau2[[#This Row],[Annee d''inscription au programme]]&"-"&[1]!Tableau2[[#This Row],[Code d''ecole]]&"-"&[1]!Tableau2[[#This Row],[Numero HM de la fille]] -> #ERROR! | K10: 8.5 | L10: 5 | M10: =SUM(K10+L10)/2 -> 6.75 | N10: 18.5 | O10: 10 | P10: =SUM(N10+O10)/2 -> 14.25
A11: Louloubi | B11: Ramatou Yahaya | C11: 20/12/2009 à Louloubi | D11: Yahaya Abdou | E11: Sae Saboua | F11: 6 | G11: 2022 | H11: 1 | I11: 6 | J11: =[1]!Tableau2[[#This Row],[Annee d''inscription au programme]]&"-"&[1]!Tableau2[[#This Row],[Code d''ecole]]&"-"&[1]!Tableau2[[#This Row],[Numero HM de la fille]] -> #ERROR! | K11: 5 | L11: 4 | M11: =SUM(K11+L11)/2 -> 4.5 | N11: 15.5 | O11: 14 | P11: =SUM(N11+O11)/2 -> 14.75
A12: Louloubi | B12: Roumanatou Chaibou | C12: 14/10/2009 à Louloubi | D12: Chaibou Salissou | E12: Sae Saboua | F12: 7 | G12: 2022 | H12: 1 | I12: 7 | J12: =[1]!Tableau2[[#This Row],[Annee d''inscription au programme]]&"-"&[1]!Tableau2[[#This Row],[Code d''ecole]]&"-"&[1]!Tableau2[[#This Row],[Numero HM de la fille]] -> #ERROR! | K12: 6 | L12: 5 | M12: =SUM(K12+L12)/2 -> 5.5 | N12: 18 | O12: 15 | P12: =SUM(N12+O12)/2 -> 16.5
A13: Louloubi | B13: Nassaiba Yacoubou | C13: 31/12/2009 à Louloubi | D13: Yacoubou Ousmane | E13: Sae Saboua | F13: 8 | G13: 2022 | H13: 1 | I13: 8 | J13: =[1]!Tableau2[[#This Row],[Annee d''inscription au programme]]&"-"&[1]!Tableau2[[#This Row],[Code d''ecole]]&"-"&[1]!Tableau2[[#This Row],[Numero HM de la fille]] -> #ERROR! | K13: 8 | L13: 6 | M13: =SUM(K13+L13)/2 -> 7 | N13: 13 | O13: 15.5 | P13: =SUM(N13+O13)/2 -> 14.25
A14: Louloubi | B14: Napissa Oumarou | C14: 31/12/2009 à Louloubi | D14: Oumarou Yacouba | E14: Sae Saboua | F14: 9 | G14: 2022 | H14: 1 | I14: 9 | J14: =[1]!Tableau2[[#This Row],[Annee d''inscription au programme]]&"-"&[1]!Tableau2[[#This Row],[Code d''ecole]]&"-"&[1]!Tableau2[[#This Row],[Numero HM de la fille]] -> #ERROR! | M14: =SUM(K14+L14)/2 -> 0 | N14: 9 | O14: 16.5 | P14: =SUM(N14+O14)/2 -> 12.75
A15: Louloubi | B15: Marliya Iliassou | C15: 31/12/2010 Louloubi | D15: Iliassou | E15: Sae Saboua | F15: 10 | G15: 2022 | H15: 1 | I15: 10 | J15: =[1]!Tableau2[[#This Row],[Annee d''inscription au programme]]&"-"&[1]!Tableau2[[#This Row],[Code d''ecole]]&"-"&[1]!Tableau2[[#This Row],[Numero HM de la fille]] -> #ERROR! | K15: 8 | L15: 3 | M15: =SUM(K15+L15)/2 -> 5.5 | N15: 14 | O15: 16 | P15: =SUM(N15+O15)/2 -> 15
A16: Louloubi | B16: Mansoura Moussa | C16: 15/12/2011 à Louloubi | D16: Moussa Oumarou | E16: Sae Saboua | F16: 11 | G16: 2022 | H16: 1 | I16: 11 | J16: =[1]!Tableau2[[#This Row],[Annee d''inscription au programme]]&"-"&[1]!Tableau2[[#This Row],[Code d''ecole]]&"-"&[1]!Tableau2[[#This Row],[Numero HM de la fille]] -> #ERROR! | K16: 9.5 | L16: 4.5 | M16: =SUM(K16+L16)/2 -> 7 | N16: 15.5 | O16: 15 | P16: =SUM(N16+O16)/2 -> 15.25
A17: Louloubi | B17: Liyanatou Oumarou | C17: 17/10/2009 à Louloubi | D17: Moumarou Harouna | E17: Sae Saboua | F17: 12 | G17: 2022 | H17: 1 | I17: 12 | J17: =[1]!Tableau2[[#This Row],[Annee d''inscription au programme]]&"-"&[1]!Tableau2[[#This Row],[Code d''ecole]]&"-"&[1]!Tableau2[[#This Row],[Numero HM de la fille]] -> #ERROR! | K17: 9 | L17: 7 | M17: =SUM(K17+L17)/2 -> 8 | N17: 18 | O17: 18.5 | P17: =SUM(N17+O17)/2 -> 18.25
A18: Louloubi | B18: Lantana Laouali | C18: 20/10/2009 à Louloubi | D18: Laouali Djadi | E18: Sae Saboua | F18: 13 | G18: 2022 | H18: 1 | I18: 13 | J18: =[1]!Tableau2[[#This Row],[Annee d''inscription au programme]]&"-"&[1]!Tableau2[[#This Row],[Code d''ecole]]&"-"&[1]!Tableau2[[#This Row],[Numero HM de la fille]] -> #ERROR! | K18: 7 | L18: 5.5 | M18: =SUM(K18+L18)/2 -> 6.25 | N18: 14.5 | O18: 13.5 | P18: =SUM(N18+O18)/2 -> 14
A19: Louloubi | B19: Habiba Aliou | C19: 05/10/2010 Louloubi | D19: Aliou Yahaya | E19: Sae Saboua | F19: 14 | G19: 2022 | H19: 1 | I19: 14 | J19: =[1]!Tableau2[[#This Row],[Annee d''inscription au programme]]&"-"&[1]!Tableau2[[#This Row],[Code d''ecole]]&"-"&[1]!Tableau2[[#This Row],[Numero HM de la fille]] -> #ERROR! | K19: 1 | L19: 2.5 | M19: =SUM(K19+L19)/2 -> 1.75 | N19: 10.25 | O19: 12.5 | P19: =SUM(N19+O19)/2 -> 11.375
A20: Louloubi | B20: Habsatou Oumarou | C20: 03/10/2010 Louloubi | D20: Oumarou Issoufou | E20: Sae Saboua | F20: 15 | G20: 2022 | H20: 1 | I20: 15 | J20: =[1]!Tableau2[[#This Row],[Annee d''inscription au programme]]&"-"&[1]!Tableau2[[#This Row],[Code d''ecole]]&"-"&[1]!Tableau2[[#This Row],[Numero HM de la fille]] -> #ERROR! | K20: 6 | L20: 5 | M20: =SUM(K20+L20)/2 -> 5.5 | N20: 15 | O20: 14.25 | P20: =SUM(N20+O20)/2 -> 14.625
A21: Louloubi | B21: Fatima Ibrahim | C21: 31/12/2010 à Louloubi | D21: Ibrahim Adamou | E21: Sae Saboua | F21: 16 | G21: 2022 | H21: 1 | I21: 16 | J21: =[1]!Tableau2[[#This Row],[Annee d''inscription au programme]]&"-"&[1]!Tableau2[[#This Row],[Code d''ecole]]&"-"&[1]!Tableau2[[#This Row],[Numero HM de la fille]] -> #ERROR! | K21: 9 | L21: 5 | M21: =SUM(K21+L21)/2 -> 7 | N21: 15 | O21: 14.25 | P21: =SUM(N21+O21)/2 -> 14.625
A22: Louloubi | B22: Farida Saàdou | C22: 30/12/2009 à Louloubi | D22: Saàdou Bala | E22: Sae Saboua | F22: 17 | G22: 2022 | H22: 1 | I22: 17 | J22: =[1]!Tableau2[[#This Row],[Annee d''inscription au programme]]&"-"&[1]!Tableau2[[#This Row],[Code d''ecole]]&"-"&[1]!Tableau2[[#This Row],[Numero HM de la fille]] -> #ERROR! | K22: 5 | L22: 4 | M22: =SUM(K22+L22)/2 -> 4.5 | N22: 10 | O22: 15.75 | P22: =SUM(N22+O22)/2 -> 12.875
A23: Louloubi | B23: Fatima Massaoudou | C23: 31/12/2010 à Louloubi | D23: Massaoudou Hamidin | E23: Sae Saboua | F23: 18 | G23: 2022 | H23: 1 | I23: 18 | J23: =[1]!Tableau2[[#This Row],[Annee d''inscription au programme]]&"-"&[1]!Tableau2[[#This Row],[Code d''ecole]]&"-"&[1]!Tableau2[[#This Row],[Numero HM de la fille]] -> #ERROR! | K23: 11.5 | L23: 6 | M23: =SUM(K23+L23)/2 -> 8.75 | N23: 15.5 | O23: 14 | P23: =SUM(N23+O23)/2 -> 14.75
A24: Louloubi | B24: Ramatou Oumarou | C24: 26/06/2009 à Louloubi | D24: Oumarou | E24: Sae Saboua | F24: 19 | G24: 2022 | H24: 1 | I24: 19 | J24: =[1]!Tableau2[[#This Row],[Annee d''inscription au programme]]&"-"&[1]!Tableau2[[#This Row],[Code d''ecole]]&"-"&[1]!Tableau2[[#This Row],[Numero HM de la fille]] -> #ERROR! | K24: 6 | L24: 2.5 | M24: =SUM(K24+L24)/2 -> 4.25 | N24: 14 | O24: 15 | P24: =SUM(N24+O24)/2 -> 14.5
A25: Louloubi | B25: Ramatou Abdoul Karim | C25: Vers 2OO9 à Louloubi | D25: Abdoul Karim | E25: Sae Saboua | F25: 20 | G25: 2022 | H25: 1 | I25: 20 | J25: =[1]!Tableau2[[#This Row],[Annee d''inscription au programme]]&"-"&[1]!Tableau2[[#This Row],[Code d''ecole]]&"-"&[1]!Tableau2[[#This Row],[Numero HM de la fille]] -> #ERROR! | K25: 6 | L25: 3 | M25: =SUM(K25+L25)/2 -> 4.5 | N25: 14.25 | O25: 16.5 | P25: =SUM(N25+O25)/2 -> 15.375
A26: Louloubi | B26: Ramanatou Ma'azou | C26: 13/03/2009 à Tsaraki Saboua | D26: Ma'azou | E26: Sae Saboua | F26: 21 | G26: 2022 | H26: 1 | I26: 21 | J26: =[1]!Tableau2[[#This Row],[Annee d''inscription au programme]]&"-"&[1]!Tableau2[[#This Row],[Code d''ecole]]&"-"&[1]!Tableau2[[#This Row],[Numero HM de la fille]] -> #ERROR! | K26: 9 | L26: 6.5 | M26: =SUM(K26+L26)/2 -> 7.75 | N26: 19 | O26: 15.5 | P26: =SUM(N26+O26)/2 -> 17.25
... A29: Kadata | B29: Chamsia Rabé | C29: Vers 2011 à Kadata | D29: Rabé Salifou | E29: Sae Saboua | F29: 24 | G29: 2022 | H29: 2 | I29: 24 | J29: =[1]!Tableau2[[#This Row],[Annee d''inscription au programme]]&"-"&[1]!Tableau2[[#This Row],[Code d''ecole]]&"-"&[1]!Tableau2[[#This Row],[Numero HM de la fille]] -> #ERROR! | K29: 7.5 | L29: 5 | M29: =SUM(K29+L29)/2 -> 6.25 | N29: 19.25 | O29: 15.5 | P29: =SUM(N29+O29)/2 -> 17.375
M30: =SUM(K30+L30)/2 -> 0 | P30: =SUM(N30+O30)/2 -> 0
A31: Kadata | B31: Fassouma Aboubacar | C31: Vers 2010 à Kadata | D31: Aboubacar Ibrahim | E31: Sae Saboua | F31: 25 | G31: 2022 | H31: 2 | I31: 26 | J31: =[1]!Tableau2[[#This Row],[Annee d''inscription au programme]]&"-"&[1]!Tableau2[[#This Row],[Code d''ecole]]&"-"&[1]!Tableau2[[#This Row],[Numero HM de la fille]] -> #ERROR! | M31: =SUM(K31+L31)/2 -> 0 | P31: =SUM(N31+O31)/2 -> 0
A32: Kadata | B32: Kadidja Ali | C32: Vers 2011 à Kadata | D32: Ali Barmo | E32: Sae Saboua | F32: 26 | G32: 2022 | H32: 2 | I32: 27 | J32: =[1]!Tableau2[[#This Row],[Annee d''inscription au programme]]&"-"&[1]!Tableau2[[#This Row],[Code d''ecole]]&"-"&[1]!Tableau2[[#This Row],[Numero HM de la fille]] -> #ERROR! | K32: 4.5 | L32: 12.75 | M32: =SUM(K32+L32)/2 -> 8.625 | N32: 16.5 | O32: 18.5 | P32: =SUM(N32+O32)/2 -> 17.5
A33: Kadata | B33: Kadija Idi | C33: Vers 2011 à Kadata | D33: Idi Issa | E33: Sae Saboua | F33: 27 | G33: 2022 | H33: 2 | I33: 28 | J33: =[1]!Tableau2[[#This Row],[Annee d''inscription au programme]]&"-"&[1]!Tableau2[[#This Row],[Code d''ecole]]&"-"&[1]!Tableau2[[#This Row],[Numero HM de la fille]] -> #ERROR! | K33: 7.25 | L33: 5 | M33: =SUM(K33+L33)/2 -> 6.125 | N33: 17.25 | O33: 14.5 | P33: =SUM(N33+O33)/2 -> 15.875
A34: Kadata | B34: Laria Habibou | C34: Vers 2011 à Kadata | D34: Habibou Hassan | E34: Sae Saboua | F34: 28 | G34: 2022 | H34: 2 | I34: 29 | J34: =[1]!Tableau2[[#This Row],[Annee d''inscription au programme]]&"-"&[1]!Tableau2[[#This Row],[Code d''ecole]]&"-"&[1]!Tableau2[[#This Row],[Numero HM de la fille]] -> #ERROR! | K34: 2.25 | L34: 4 | M34: =SUM(K34+L34)/2 -> 3.125 | N34: 17 | O34: 14.4 | P34: =SUM(N34+O34)/2 -> 15.7
A35: Kadata | B35: Manira Halilou | C35: Vers 2011 à Kadata | D35: Halilou Maàzou | E35: Sae Saboua | F35: 29 | G35: 2022 | H35: 2 | I35: 30 | J35: =[1]!Tableau2[[#This Row],[Annee d''inscription au programme]]&"-"&[1]!Tableau2[[#This Row],[Code d''ecole]]&"-"&[1]!Tableau2[[#This Row],[Numero HM de la fille]] -> #ERROR! | K35: 7.25 | L35: 7.75 | M35: =SUM(K35+L35)/2 -> 7.5 | N35: 16.25 | O35: 14 | P35: =SUM(N35+O35)/2 -> 15.125
A36: Kadata | B36: Ousseina Garba | C36: Vers 2010 à Kadata | D36: Garba Mahaman | E36: Sae Saboua | F36: 30 | G36: 2022 | H36: 2 | I36: 31 | J36: =[1]!Tableau2[[#This Row],[Annee d''inscription au programme]]&"-"&[1]!Tableau2[[#This Row],[Code d''ecole]]&"-"&[1]!Tableau2[[#This Row],[Numero HM de la fille]] -> #ERROR! | K36: 2.5 | L36: 12.25 | M36: =SUM(K36+L36)/2 -> 7.375 | N36: 18.25 | O36: 15 | P36: =SUM(N36+O36)/2 -> 16.625
A37: Kadata | B37: Rapia Idi | C37: Vers 2010 à Kadata | D37: Idi Malan Abdou | E37: Sae Saboua | F37: 31 | G37: 2022 | H37: 2 | I37: 32 | J37: =[1]!Tableau2[[#This Row],[Annee d''inscription au programme]]&"-"&[1]!Tableau2[[#This Row],[Code d''ecole]]&"-"&[1]!Tableau2[[#This Row],[Numero HM de la fille]] -> #ERROR! | K37: 2.5 | L37: 8.75 | M37: =SUM(K37+L37)/2 -> 5.625 | N37: 17.75 | O37: 16 | P37: =SUM(N37+O37)/2 -> 16.875
A38: Kadata | B38: Safina Kabirou | C38: Vers 2011 à Kadata | D38: Kabirou Moussa | E38: Sae Saboua | F38: 32 | G38: 2022 | H38: 2 | I38: 33 | J38: =[1]!Tableau2[[#This Row],[Annee d''inscription au programme]]&"-"&[1]!Tableau2[[#This Row],[Code d''ecole]]&"-"&[1]!Tableau2[[#This Row],[Numero HM de la fille]] -> #ERROR! | M38: =SUM(K38+L38)/2 -> 0 | P38: =SUM(N38+O38)/2 -> 0
A39: Kadata | B39: Safia Yahaya | C39: Vers 2010 à Kadata | D39: Yahaya Tsalha | E39: Sae Saboua | F39: 33 | G39: 2022 | H39: 2 | I39: 34 | J39: =[1]!Tableau2[[#This Row],[Annee d''inscription au programme]]&"-"&[1]!Tableau2[[#This Row],[Code d''ecole]]&"-"&[1]!Tableau2[[#This Row],[Numero HM de la fille]] -> #ERROR! | K39: 6.5 | L39: 4.5 | M39: =SUM(K39+L39)/2 -> 5.5 | N39: 17 | O39: 16.5 | P39: =SUM(N39+O39)/2 -> 16.75
F40: 32 | M40: =SUM(K40+L40)/2 -> 0 | P40: =SUM(N40+O40)/2 -> 0
A41: Kadata | B41: Souéba Moussa | C41: Vers 2011 à Kadata | D41: Moussa Issoufou | E41: Sae Saboua | F41: 34 | G41: 2022 | H41: 2 | I41: 36 | J41: =[1]!Tableau2[[#This Row],[Annee d''inscription au programme]]&"-"&[1]!Tableau2[[#This Row],[Code d''ecole]]&"-"&[1]!Tableau2[[#This Row],[Numero HM de la fille]] -> #ERROR! | K41: 6 | L41: 8.75 | M41: =SUM(K41+L41)/2 -> 7.375 | N41: 16.5 | O41: 16.5 | P41: =SUM(N41+O41)/2 -> 16.5
A42: Kadata | B42: Zeinab Ibrahim | C42: Vers 2011 à Kadata | D42: Ibrahim | E42: Sae Saboua | F42: 35 | G42: 2022 | H42: 2 | I42: 37 | J42: =[1]!Tableau2[[#This Row],[Annee d''inscription au programme]]&"-"&[1]!Tableau2[[#This Row],[Code d''ecole]]&"-"&[1]!Tableau2[[#This Row],[Numero HM de la fille]] -> #ERROR! | K42: 8.25 | L42: 7.25 | M42: =SUM(K42+L42)/2 -> 7.75 | N42: 19 | O42: 17 | P42: =SUM(N42+O42)/2 -> 18
...

Sheet Groupe Temoin 
A2: BASE CONTRÔLE CM2
A3: 2022-2023
G4: Identifiant de la fille | K4: BASE-LINE | N4: END-LINE | Q4: Examens
A5: Ecole | B5: Nom et Prénom | C5: Date et lieu de naissance | D5: Nom et prénom du père | E5: Nom de la commune | F5: Nombre des filles | G5: Annee d'inscription au programme | H5: Code d'ecole | I5: Numero HM de la fille | J5: Identifiant Unique | K5: Français /20 | L5: Mathématique /20 | M5: Moyenne Générale/40 | N5: Français/20 | O5: Mathématique/20 | P5: Moyenne Générale /40 | Q5: 1ère composition/10 | R5: 2è composition/10 | S5: 3è composition | T5: Moyenne générale | U5: Commentaire | V5: Situation (fin d'annee scolaire 2022-2023)
A6: Mata Milki | B6: Aicha Inoussa | C6: 31/12/11 à Mata Mulki | D6: Inoussa | E6: Sae Saboua | F6: 1 | G6: 2022 | H6: 1 | I6: 1 | J6: ='Groupe Temoin '!$G6&"-"&'Groupe Temoin '!$H6&"-"&'Groupe Temoin '!$I6 -> 2022-1-1 | K6: 4.5 | L6: 10 | M6: =AVERAGE('Groupe Temoin '!$K6+'Groupe Temoin '!$L6)/2 -> 7.25 | N6: 10 | O6: 10 | P6: =AVERAGE('Groupe Temoin '!$N6+'Groupe Temoin '!$O6)/2 -> 10
A7: Mata Milki | B7: Biba Abdou | C7: 31/12/10 à Mata Mulki | D7: Abdou | E7: Sae Saboua | F7: 2 | G7: 2022 | H7: 1 | I7: 2 | J7: ='Groupe Temoin '!$G7&"-"&'Groupe Temoin '!$H7&"-"&'Groupe Temoin '!$I7 -> 2022-1-2 | K7: 6 | L7: 9 | M7: =AVERAGE('Groupe Temoin '!$K7+'Groupe Temoin '!$L7)/2 -> 7.5 | N7: 4 | O7: 2 | P7: =AVERAGE('Groupe Temoin '!$N7+'Groupe Temoin '!$O7)/2 -> 3
A8: Mata Milki | B8: Balkissa Achirou | C8: 31/12/10 à Mata Mulki | D8: Achirou | E8: Sae Saboua | F8: 3 | G8: 2022 | H8: 1 | I8: 3 | J8: ='Groupe Temoin '!$G8&"-"&'Groupe Temoin '!$H8&"-"&'Groupe Temoin '!$I8 -> 2022-1-3 | K8: 6.5 | L8: 14 | M8: =AVERAGE('Groupe Temoin '!$K8+'Groupe Temoin '!$L8)/2 -> 10.25 | N8: 4 | O8: 7.5 | P8: =AVERAGE('Groupe Temoin '!$N8+'Groupe Temoin '!$O8)/2 -> 5.75
A9: Mata Milki | B9: Firdaoussi Ali | C9: 31/12/11 à Mata Mulki | D9: Ali | E9: Sae Saboua | F9: 4 | G9: 2022 | H9: 1 | I9: 4 | J9: ='Groupe Temoin '!$G9&"-"&'Groupe Temoin '!$H9&"-"&'Groupe Temoin '!$I9 -> 2022-1-4 | K9: 8.5 | L9: 14.5 | M9: =AVERAGE('Groupe Temoin '!$K9+'Groupe Temoin '!$L9)/2 -> 11.5 | N9: 3.5 | O9: 6 | P9: =AVERAGE('Groupe Temoin '!$N9+'Groupe Temoin '!$O9)/2 -> 4.75
A10: Mata Milki | B10: Fatiha Abdoul Aziz | C10: 31/12/11 à Mata Mulki | D10: Abdoul Aziz | E10: Sae Saboua | F10: 5 | G10: 2022 | H10: 1 | I10: 5 | J10: ='Groupe Temoin '!$G10&"-"&'Groupe Temoin '!$H10&"-"&'Groupe Temoin '!$I10 -> 2022-1-5 | K10: 3 | L10: 3 | M10: =AVERAGE('Groupe Temoin '!$K10+'Groupe Temoin '!$L10)/2 -> 3 | N10: 2 | O10: 2 | P10: =AVERAGE('Groupe Temoin '!$N10+'Groupe Temoin '!$O10)/2 -> 2
A11: Mata Milki | B11: Hanafiya Baraou | C11: 31/12/11 à Mata Mulki | D11: Baraou | E11: Sae Saboua | F11: 6 | G11: 2022 | H11: 1 | I11: 6 | J11: ='Groupe Temoin '!$G11&"-"&'Groupe Temoin '!$H11&"-"&'Groupe Temoin '!$I11 -> 2022-1-6 | K11: 5.5 | L11: 10 | M11: =AVERAGE('Groupe Temoin '!$K11+'Groupe Temoin '!$L11)/2 -> 7.75 | N11: 4.25 | O11: 10 | P11: =AVERAGE('Groupe Temoin '!$N11+'Groupe Temoin '!$O11)/2 -> 7.125
A12: Mata Milki | B12: Massa'ouda Sidi | C12: 31/12/11 à Mata Mulki | D12: Sidi | E12: Sae Saboua | F12: 7 | G12: 2022 | H12: 1 | I12: 7 | J12: ='Groupe Temoin '!$G12&"-"&'Groupe Temoin '!$H12&"-"&'Groupe Temoin '!$I12 -> 2022-1-7 | K12: 6 | L12: 10 | M12: =AVERAGE('Groupe Temoin '!$K12+'Groupe Temoin '!$L12)/2 -> 8 | N12: 6 | O12: 6 | P12: =AVERAGE('Groupe Temoin '!$N12+'Groupe Temoin '!$O12)/2 -> 6
A13: Mata Milki | B13: Malika Laouali | C13: 31/12/11 à Mata Mulki | D13: Laouali | E13: Sae Saboua | F13: 8 | G13: 2022 | H13: 1 | I13: 8 | J13: ='Groupe Temoin '!$G13&"-"&'Groupe Temoin '!$H13&"-"&'Groupe Temoin '!$I13 -> 2022-1-8 | K13: 2.5 | L13: 5 | M13: =AVERAGE('Groupe Temoin '!$K13+'Groupe Temoin '!$L13)/2 -> 3.75 | N13: 6 | O13: 7 | P13: =AVERAGE('Groupe Temoin '!$N13+'Groupe Temoin '!$O13)/2 -> 6.5
A14: Mata Milki | B14: Mariama Garba | C14: 31/12/10 à Mata Mulki | D14: Garba | E14: Sae Saboua | F14: 9 | G14: 2022 | H14: 1 | I14: 9 | J14: ='Groupe Temoin '!$G14&"-"&'Groupe Temoin '!$H14&"-"&'Groupe Temoin '!$I14 -> 2022-1-9 | K14: 4 | L14: 13 | M14: =AVERAGE('Groupe Temoin '!$K14+'Groupe Temoin '!$L14)/2 -> 8.5 | N14: 6.5 | O14: 5 | P14: =AVERAGE('Groupe Temoin '!$N14+'Groupe Temoin '!$O14)/2 -> 5.75
A15: Mata Milki | B15: Nana Na'ima Tassiou | C15: 31/12/11 à Mata Mulki | D15: Tassiou | E15: Sae Saboua | F15: 10 | G15: 2022 | H15: 1 | I15: 10 | J15: ='Groupe Temoin '!$G15&"-"&'Groupe Temoin '!$H15&"-"&'Groupe Temoin '!$I15 -> 2022-1-10 | K15: 5.5 | L15: 13 | M15: =AVERAGE('Groupe Temoin '!$K15+'Groupe Temoin '!$L15)/2 -> 9.25 | N15: 7 | O15: 5.5 | P15: =AVERAGE('Groupe Temoin '!$N15+'Groupe Temoin '!$O15)/2 -> 6.25
A16: Mata Milki | B16: Ousseina Issaka | C16: 31/12/11 à Mata Mulki | D16: Issaka | E16: Sae Saboua | F16: 11 | G16: 2022 | H16: 1 | I16: 11 | J16: ='Groupe Temoin '!$G16&"-"&'Groupe Temoin '!$H16&"-"&'Groupe Temoin '!$I16 -> 2022-1-11 | K16: 6.5 | L16: 10 | M16: =AVERAGE('Groupe Temoin '!$K16+'Groupe Temoin '!$L16)/2 -> 8.25 | N16: 1.5 | O16: 9 | P16: =AVERAGE('Groupe Temoin '!$N16+'Groupe Temoin '!$O16)/2 -> 5.25
A17: Mata Milki | B17: Rachida Abdou | C17: 31/12/11 à Mata Mulki | D17: Abdou | E17: Sae Saboua | F17: 12 | G17: 2022 | H17: 1 | I17: 12 | J17: ='Groupe Temoin '!$G17&"-"&'Groupe Temoin '!$H17&"-"&'Groupe Temoin '!$I17 -> 2022-1-12 | K17: 5 | L17: 10 | M17: =AVERAGE('Groupe Temoin '!$K17+'Groupe Temoin '!$L17)/2 -> 7.5 | N17: 2.75 | O17: 2 | P17: =AVERAGE('Groupe Temoin '!$N17+'Groupe Temoin '!$O17)/2 -> 2.375
... A26: Mata Milki | B26: Habsatou Ibrahim | C26: 31/12/11 à Mata Mulki | D26: Ibrahim | E26: Sae Saboua | F26: 21 | G26: 2022 | H26: 1 | I26: 21 | J26: ='Groupe Temoin '!$G26&"-"&'Groupe Temoin '!$H26&"-"&'Groupe Temoin '!$I26 -> 2022-1-21 | K26: 2 | L26: 6.5 | M26: =AVERAGE('Groupe Temoin '!$K26+'Groupe Temoin '!$L26)/2 -> 4.25 | N26: 6 | O26: 7 | P26: =AVERAGE('Groupe Temoin '!$N26+'Groupe Temoin '!$O26)/2 -> 6.5
A27: Mountarou 1 | B27: Amira Issaka | D27: Issaka | E27: Sae Saboua | F27: 22 | G27: 2022 | H27: 2 | I27: 22 | J27: ='Groupe Temoin '!$G27&"-"&'Groupe Temoin '!$H27&"-"&'Groupe Temoin '!$I27 -> 2022-2-22 | K27: 5 | L27: 11.5 | M27: =AVERAGE('Groupe Temoin '!$K27+'Groupe Temoin '!$L27)/2 -> 8.25 | N27: 10 | O27: 7.5 | P27: =AVERAGE('Groupe Temoin '!$N27+'Groupe Temoin '!$O27)/2 -> 8.75
A28: Mountarou 1 | B28: Fadila Yaou | D28: Ya'ou | E28: Sae Saboua | F28: 23 | G28: 2022 | H28: 2 | I28: 23 | J28: ='Groupe Temoin '!$G28&"-"&'Groupe Temoin '!$H28&"-"&'Groupe Temoin '!$I28 -> 2022-2-23 | K28: 2.5 | L28: 4 | M28: =AVERAGE('Groupe Temoin '!$K28+'Groupe Temoin '!$L28)/2 -> 3.25 | N28: 2.5 | O28: 7 | P28: =AVERAGE('Groupe Temoin '!$N28+'Groupe Temoin '!$O28)/2 -> 4.75
A29: Mountarou 1 | B29: Zahara'ou Zayya | D29: Zayya | E29: Sae Saboua | F29: 24 | G29: 2022 | H29: 2 | I29: 24 | J29: ='Groupe Temoin '!$G29&"-"&'Groupe Temoin '!$H29&"-"&'Groupe Temoin '!$I29 -> 2022-2-24 | K29: 3.5 | L29: 8 | M29: =AVERAGE('Groupe Temoin '!$K29+'Groupe Temoin '!$L29)/2 -> 5.75 | N29: 4 | O29: 6 | P29: =AVERAGE('Groupe Temoin '!$N29+'Groupe Temoin '!$O29)/2 -> 5
A30: Mountarou 1 | B30: Mansoura Aboubacar | D30: Aboubacar | E30: Sae Saboua | F30: 26 | G30: 2022 | H30: 2 | I30: 26 | J30: ='Groupe Temoin '!$G30&"-"&'Groupe Temoin '!$H30&"-"&'Groupe Temoin '!$I30 -> 2022-2-26 | K30: 3 | L30: 3 | M30: =AVERAGE('Groupe Temoin '!$K30+'Groupe Temoin '!$L30)/2 -> 3 | N30: 2 | O30: 4 | P30: =AVERAGE('Groupe Temoin '!$N30+'Groupe Temoin '!$O30)/2 -> 3
A31: Mountarou 1 | B31: Anissa Sani | D31: Sani | E31: Sae Saboua | F31: 27 | G31: 2022 | H31: 2 | I31: 27 | J31: ='Groupe Temoin '!$G31&"-"&'Groupe Temoin '!$H31&"-"&'Groupe Temoin '!$I31 -> 2022-2-27 | K31: 7 | L31: 8 | M31: =AVERAGE('Groupe Temoin '!$K31+'Groupe Temoin '!$L31)/2 -> 7.5 | N31: 8 | O31: 6 | P31: =AVERAGE('Groupe Temoin '!$N31+'Groupe Temoin '!$O31)/2 -> 7
A32: Mountarou 1 | B32: Yasmina Yaou | D32: Yaou | E32: Sae Saboua | F32: 28 | G32: 2022 | H32: 2 | I32: 28 | J32: ='Groupe Temoin '!$G32&"-"&'Groupe Temoin '!$H32&"-"&'Groupe Temoin '!$I32 -> 2022-2-28 | K32: 7.5 | L32: 9 | M32: =AVERAGE('Groupe Temoin '!$K32+'Groupe Temoin '!$L32)/2 -> 8.25 | N32: 6 | O32: 8 | P32: =AVERAGE('Groupe Temoin '!$N32+'Groupe Temoin '!$O32)/2 -> 7
A33: Mountarou 1 | B33: Manira Sani | D33: Sani | E33: Sae Saboua | F33: 29 | G33: 2022 | H33: 2 | I33: 29 | J33: ='Groupe Temoin '!$G33&"-"&'Groupe Temoin '!$H33&"-"&'Groupe Temoin '!$I33 -> 2022-2-29 | K33: 5 | L33: 9.5 | M33: =AVERAGE('Groupe Temoin '!$K33+'Groupe Temoin '!$L33)/2 -> 7.25 | N33: 6 | O33: 2.5 | P33: =AVERAGE('Groupe Temoin '!$N33+'Groupe Temoin '!$O33)/2 -> 4.25
A34: Mountarou 1 | B34: Rafia Idi | D34: Idi | E34: Sae Saboua | F34: 30 | G34: 2022 | H34: 2 | I34: 30 | J34: ='Groupe Temoin '!$G34&"-"&'Groupe Temoin '!$H34&"-"&'Groupe Temoin '!$I34 -> 2022-2-30 | K34: 5.5 | L34: 4.5 | M34: =AVERAGE('Groupe Temoin '!$K34+'Groupe Temoin '!$L34)/2 -> 5 | N34: 4.5 | O34: 6.25 | P34: =AVERAGE('Groupe Temoin '!$N34+'Groupe Temoin '!$O34)/2 -> 5.375
A35: Mountarou 1 | B35: Nana Samira Sani Saidou | D35: Sani Saidou | E35: Sae Saboua | F35: 31 | G35: 2022 | H35: 2 | I35: 31 | J35: ='Groupe Temoin '!$G35&"-"&'Groupe Temoin '!$H35&"-"&'Groupe Temoin '!$I35 -> 2022-2-31 | K35: 10.5 | L35: 3.5 | M35: =AVERAGE('Groupe Temoin '!$K35+'Groupe Temoin '!$L35)/2 -> 7 | N35: 4 | O35: 1 | P35: =AVERAGE('Groupe Temoin '!$N35+'Groupe Temoin '!$O35)/2 -> 2.5
A36: Mountarou 1 | B36: Fatima Sani | D36: Sani | E36: Sae Saboua | F36: 32 | G36: 2022 | H36: 2 | I36: 32 | J36: ='Groupe Temoin '!$G36&"-"&'Groupe Temoin '!$H36&"-"&'Groupe Temoin '!$I36 -> 2022-2-32 | K36: 7 | L36: 11.5 | M36: =AVERAGE('Groupe Temoin '!$K36+'Groupe Temoin '!$L36)/2 -> 9.25 | N36: 14 | O36: 10.5 | P36: =AVERAGE('Groupe Temoin '!$N36+'Groupe Temoin '!$O36)/2 -> 12.25
A37: Mountarou 1 | B37: Haoua'ou Issaka | D37: Issaka | E37: Sae Saboua | F37: 33 | G37: 2022 | H37: 2 | I37: 33 | J37: ='Groupe Temoin '!$G37&"-"&'Groupe Temoin '!$H37&"-"&'Groupe Temoin '!$I37 -> 2022-2-33 | K37: 5 | L37: 6.5 | M37: =AVERAGE('Groupe Temoin '!$K37+'Groupe Temoin '!$L37)/2 -> 5.75 | N37: 9.25 | O37: 3.5 | P37: =AVERAGE('Groupe Temoin '!$N37+'Groupe Temoin '!$O37)/2 -> 6.375
A38: Mountarou 1 | B38: Soumaya Zouladeini | D38: Zouladeini | E38: Sae Saboua | F38: 34 | G38: 2022 | H38: 2 | I38: 34 | J38: ='Groupe Temoin '!$G38&"-"&'Groupe Temoin '!$H38&"-"&'Groupe Temoin '!$I38 -> 2022-2-34 | K38: 4 | L38: 6.5 | M38: =AVERAGE('Groupe Temoin '!$K38+'Groupe Temoin '!$L38)/2 -> 5.25 | N38: 1.5 | O38: 6 | P38: =AVERAGE('Groupe Temoin '!$N38+'Groupe Temoin '!$O38)/2 -> 3.75
... A45: Karambi Sofoua | B45: Rakia Maman Nassirou | D45: Maman Nassirou | E45: Sae Saboua | F45: 42 | G45: 2022 | H45: 3 | I45: 637 | J45: ='Groupe Temoin '!$G45&"-"&'Groupe Temoin '!$H45&"-"&'Groupe Temoin '!$I45 -> 2022-3-637 | K45: 1 | L45: 2.5 | M45: =AVERAGE('Groupe Temoin '!$K45+'Groupe Temoin '!$L45)/2 -> 1.75 | N45: 1.5 | O45: 5 | P45: =AVERAGE('Groupe Temoin '!$N45+'Groupe Temoin '!$O45)/2 -> 3.25
A46: Karambi Sofoua | B46: Nisseifa Yacouba | D46: Yacouba | E46: Sae Saboua | F46: 43 | G46: 2022 | H46: 3 | I46: 43 | J46: ='Groupe Temoin '!$G46&"-"&'Groupe Temoin '!$H46&"-"&'Groupe Temoin '!$I46 -> 2022-3-43 | K46: 7.5 | L46: 10 | M46: =AVERAGE('Groupe Temoin '!$K46+'Groupe Temoin '!$L46)/2 -> 8.75 | P46: =AVERAGE('Groupe Temoin '!$N46+'Groupe Temoin '!$O46)/2 -> 0
A47: Karambi Sofoua | B47: Soueba Kabirou | D47: Kabirou | E47: Sae Saboua | F47: 44 | G47: 2022 | H47: 3 | I47: 631 | J47: ='Groupe Temoin '!$G47&"-"&'Groupe Temoin '!$H47&"-"&'Groupe Temoin '!$I47 -> 2022-3-631 | K47: 8 | L47: 11.5 | M47: =AVERAGE('Groupe Temoin '!$K47+'Groupe Temoin '!$L47)/2 -> 9.75 | N47: 4.5 | O47: 5 | P47: =AVERAGE('Groupe Temoin '!$N47+'Groupe Temoin '!$O47)/2 -> 4.75
A48: Karambi Sofoua | B48: Rahila Moustapha | D48: Moustapha | E48: Sae Saboua | F48: 45 | G48: 2022 | H48: 3 | I48: 646 | J48: ='Groupe Temoin '!$G48&"-"&'Groupe Temoin '!$H48&"-"&'Groupe Temoin '!$I48 -> 2022-3-646 | K48: 4 | L48: 9.5 | M48: =AVERAGE('Groupe Temoin '!$K48+'Groupe Temoin '!$L48)/2 -> 6.75 | N48: 10 | O48: 7 | P48: =AVERAGE('Groupe Temoin '!$N48+'Groupe Temoin '!$O48)/2 -> 8.5
A49: Karambi Sofoua | B49: Mariama Mamouda | D49: Mamouda | E49: Sae Saboua | F49: 46 | G49: 2022 | H49: 3 | I49: 633 | J49: ='Groupe Temoin '!$G49&"-"&'Groupe Temoin '!$H49&"-"&'Groupe Temoin '!$I49 -> 2022-3-633 | K49: 4 | L49: 8 | M49: =AVERAGE('Groupe Temoin '!$K49+'Groupe Temoin '!$L49)/2 -> 6 | N49: 0 | O49: 0 | P49: =AVERAGE('Groupe Temoin '!$N49+'Groupe Temoin '!$O49)/2 -> 0
A50: Karambi Sofoua | B50: Tsalouba Nouhou | D50: Nouhou | E50: Sae Saboua | F50: 47 | G50: 2022 | H50: 3 | I50: 641 | J50: ='Groupe Temoin '!$G50&"-"&'Groupe Temoin '!$H50&"-"&'Groupe Temoin '!$I50 -> 2022-3-641 | K50: 1 | L50: 3 | M50: =AVERAGE('Groupe Temoin '!$K50+'Groupe Temoin '!$L50)/2 -> 2 | N50: 0 | O50: 0 | P50: =AVERAGE('Groupe Temoin '!$N50+'Groupe Temoin '!$O50)/2 -> 0
A51: Karambi Sofoua | B51: Ainaou Mahajourou | D51: Mahajourou | E51: Sae Saboua | F51: 48 | G51: 2022 | H51: 3 | I51: 644 | J51: ='Groupe Temoin '!$G51&"-"&'Groupe Temoin '!$H51&"-"&'Groupe Temoin '!$I51 -> 2022-3-644 | K51: 5 | L51: 7.5 | M51: =AVERAGE('Groupe Temoin '!$K51+'Groupe Temoin '!$L51)/2 -> 6.25 | N51: 6 | O51: 4 | P51: =AVERAGE('Groupe Temoin '!$N51+'Groupe Temoin '!$O51)/2 -> 5
A52: Karambi Sofoua | B52: Laouratou Abdoullahi | D52: Abdoullahi | E52: Sae Saboua | F52: 49 | G52: 2022 | H52: 3 | I52: 635 | J52: ='Groupe Temoin '!$G52&"-"&'Groupe Temoin '!$H52&"-"&'Groupe Temoin '!$I52 -> 2022-3-635 | K52: 1 | L52: 9.5 | M52: =AVERAGE('Groupe Temoin '!$K52+'Groupe Temoin '!$L52)/2 -> 5.25 | N52: 5.5 | O52: 6 | P52: =AVERAGE('Groupe Temoin '!$N52+'Groupe Temoin '!$O52)/2 -> 5.75
A53: Karambi Sofoua | B53: Rachida Rabiou | D53: Rabiou | E53: Sae Saboua | F53: 50 | G53: 2022 | H53: 3 | I53: 645 | J53: ='Groupe Temoin '!$G53&"-"&'Groupe Temoin '!$H53&"-"&'Groupe Temoin '!$I53 -> 2022-3-645 | K53: 5.5 | L53: 7 | M53: =AVERAGE('Groupe Temoin '!$K53+'Groupe Temoin '!$L53)/2 -> 6.25 | N53: 8 | O53: 8 | P53: =AVERAGE('Groupe Temoin '!$N53+'Groupe Temoin '!$O53)/2 -> 8
A54: Karambi Sofoua | B54: Azima Abdoul Moumouni | D54: Abdoul Moumouni | E54: Sae Saboua | F54: 51 | G54: 2022 | H54: 3 | I54: 634 | J54: ='Groupe Temoin '!$G54&"-"&'Groupe Temoin '!$H54&"-"&'Groupe Temoin '!$I54 -> 2022-3-634 | K54: 5 | L54: 6.5 | M54: =AVERAGE('Groupe Temoin '!$K54+'Groupe Temoin '!$L54)/2 -> 5.75 | N54: 2.5 | O54: 6 | P54: =AVERAGE('Groupe Temoin '!$N54+'Groupe Temoin '!$O54)/2 -> 4.25
A55: Karambi Sofoua | B55: Aicha Haladou | D55: Haladou | E55: Sae Saboua | F55: 52 | G55: 2022 | H55: 3 | I55: 638 | J55: ='Groupe Temoin '!$G55&"-"&'Groupe Temoin '!$H55&"-"&'Groupe Temoin '!$I55 -> 2022-3-638 | K55: 2 | L55: 10 | M55: =AVERAGE('Groupe Temoin '!$K55+'Groupe Temoin '!$L55)/2 -> 6 | N55: 5 | O55: 14 | P55: =AVERAGE('Groupe Temoin '!$N55+'Groupe Temoin '!$O55)/2 -> 9.5
...

Sheet Matching 2023
A2: Matching 2023 CM2
A4: Code | B4: Site intervention | C4: Site contrôle
A5: 1 | B5: Louloubi | C5: Karambi Sofoua
A6: 2 | B6: Kadata | C6: Mountarou 1
A7: 3 | B7: Barouana | C7: Mata Milki
