Workbook

Sheet Notes des filles des CM
A1: Région de Maradi
A2: DREN de Maradi
A3: IREP/P de Maradi
A4: IEP/P de Safo
C6: Situation des élèves filles des classes CM1 et CM2
C8: a)Les élèves FILLES du CM1 | P8: b)Les élèves FILLES du CM2
A9: Etablissement | B9: PRENOMS ET NOMS | C9: Sexe | D9: 1ere Evaluation | E9: 2ème Evaluation | F9: 3ème COMPO | G9: Moyenne | H9: Situation Finale
G10: Annuelle | N10: Etablissement | O10: PRENOMS ET NOMS | Q10: Sexe | R10: Dates et Lieu de Naissances | T10: Statut | U10: 1er trim | V10: 2eme trim | W10: moy CFEPD | X10: Situations FINALES
A12: Ecole de Safo Nassaraoua
A13: Safo Nassaraoua | B13: Faouziya Harouna | C13: F | D13: 8.44 | E13: 8.73 | F13: 8.62 | G13: =(D13+E13+F13)/3 -> 8.5966667 | H13: Passe | N13: Safo Nassaraoua | O13: Amira | P13: Ali | Q13: F | R13: 40874 | S13: Safo NASSARAOUA | T13: Passant | U13: 5.2 | V13: 6.11 | W13: non Admise | X13: Redouble
A14: Safo Nassaraoua | B14: Chamsiya Chitou | C14: F | D14: 6.63 | E14: 5.78 | F14: 5.22 | G14: =(D14+E14+F14)/3 -> 5.8766667 | H14: Passe | N14: Safo Nassaraoua | O14: Balkissa | P14: Daouda | Q14: F | R14: 40909 | S14: Safo NASSARAOUA | T14: Passant | U14: 4.3 | V14: 5.29 | W14: non Admise | X14: Redouble
A15: Safo Nassaraoua | B15: Hanifa Amadou | C15: F | D15: 8.27 | E15: 7.98 | F15: 8.13 | G15: =(D15+E15+F15)/3 -> 8.1266667 | H15: Passe | N15: Safo Nassaraoua | O15: Hassia | P15: Ali | Q15: F | R15: 40909 | S15: Safo NASSARAOUA | T15: Passant | U15: 5.29 | V15: 6.14 | W15: non Admise | X15: Redouble
A16: Safo Nassaraoua | B16: Rafia Tanimoune | C16: F | D16: 7.41 | E16: 6.83 | F16: 6.66 | G16: =(D16+E16+F16)/3 -> 6.9666667 | H16: Passe | N16: Safo Nassaraoua | O16: Laouratou | P16: Minnirou | Q16: F | R16: 40775 | S16: Safo NASSARAOUA | T16: Passant | U16: 7.38 | V16: 8 | W16: 5.21 | X16: CEG
A17: Safo Nassaraoua | B17: Fatima Salissou | C17: F | D17: 4.69 | E17: 4.25 | F17: 5.14 | G17: =(D17+E17+F17)/3 -> 4.6933333 | H17: Passe | N17: Safo Nassaraoua | O17: Mouhoussina | P17: Issoufou | Q17: F | R17: 40909 | S17: Safo NASSARAOUA | T17: Passant | U17: 4.57 | V17: 0 | W17: non Admise | X17: Redouble
A18: Safo Nassaraoua | B18: Zeinab Harouna | C18: F | D18: 5.21 | E18: 4.66 | F18: 3.94 | G18: =(D18+E18+F18)/3 -> 4.6033333 | H18: Passe | N18: Safo Nassaraoua | O18: Nana Moustahida | P18: Idi | Q18: F | R18: 41396 | S18: Safo NASSARAOUA | T18: Passant | U18: 6.29 | V18: 7.91 | W18: 6.36 | X18: CEG
A19: Safo Nassaraoua | B19: Manira Laouali | C19: F | D19: 6.01 | E19: 5.24 | F19: 3.55 | G19: =(D19+E19+F19)/3 -> 4.9333333 | H19: Passe | N19: Safo Nassaraoua | O19: Nana Bassira | P19: Chitou | Q19: F | R19: 40909 | S19: Safo NASSARAOUA | T19: Passant | U19: 5.04 | V19: 5.52 | W19: non Admise | X19: Redouble
A20: Safo Nassaraoua | B20: Aziza Nouhou | C20: F | D20: 4.78 | E20: 4.23 | F20: 5.18 | G20: =(D20+E20+F20)/3 -> 4.73 | H20: Passe | N20: Safo Nassaraoua | O20: Nana Kaoussar | P20: Tassiou | Q20: F | R20: 41368 | S20: Safo NASSARAOUA | T20: Passant | U20: 6.89 | V20: 8.67 | W20: 7.18 | X20: CEG
A21: Safo Nassaraoua | B21: Mouhoussina Dayabou | C21: F | D21: 5.21 | E21: 4.39 | F21: 3.96 | G21: =(D21+E21+F21)/3 -> 4.52 | H21: Passe | N21: Safo Nassaraoua | O21: Samira | P21: Abdoulaye | Q21: F | R21: 40909 | S21: Safo NASSARAOUA | T21: Passant | U21: 6.01 | V21: 5.52 | W21: 6.02 | X21: CEG
A22: Safo Nassaraoua | B22: Oumma abiha Saminou | C22: F | D22: 8.22 | E22: 7.54 | F22: 7.41 | G22: =(D22+E22+F22)/3 -> 7.7233333 | H22: Passe | N22: Safo Nassaraoua | O22: Soumaya | P22: Youchaou | Q22: F | R22: 40659 | S22: Safo NASSARAOUA | T22: Passant | U22: 5.1 | V22: 5.26 | W22: non Admise | X22: Redouble
A23: Safo Nassaraoua | B23: Oumaeira Kabirou | C23: F | D23: 5.62 | E23: 5.17 | F23: 4.44 | G23: =(D23+E23+F23)/3 -> 5.0766667 | H23: Passe | N23: Safo Nassaraoua | O23: Zaharaou | P23: Souley | Q23: F | R23: 40179 | S23: Safo NASSARAOUA | T23: Redoublant | U23: 4.35 | V23: 4.2 | W23: 4.65 | X23: CEG
A24: Safo Nassaraoua | B24: Souraya Illa | C24: F | D24: 4.24 | E24: 4.99 | F24: 4.95 | G24: =(D24+E24+F24)/3 -> 4.7266667 | H24: Passe | N24: Safo Nassaraoua | O24: Farida | P24: Mahamane | Q24: F | R24: 40673 | S24: Safo NASSARAOUA | T24: Redoublant | U24: 4.66 | V24: 4.02 | W24: 4.5 | X24: CEG
A25: Safo Nassaraoua | B25: Nana Zaharaou Nouhou | C25: F | D25: 4.59 | E25: 3.96 | F25: 4.96 | G25: =(D25+E25+F25)/3 -> 4.5033333 | H25: Passe | O25: SAFO DAN ALI
A26: Safo Nassaraoua | B26: Mariama Rabé | C26: F | D26: 3.94 | E26: 4.97 | F26: 4.86 | G26: =(D26+E26+F26)/3 -> 4.59 | H26: Passe | N26: Safo Dan Ali | O26: Aicha | P26: Issaka | Q26: F | R26: 40909 | S26: Safo Dan Ali | T26: Passant | U26: 6.64 | V26: 5.8 | W26: 4.56 | X26: CEG
A27: Safo Nassaraoua | B27: Roufaatou Abdousalam | C27: F | D27: 3.96 | E27: 4.85 | F27: 4.91 | G27: =(D27+E27+F27)/3 -> 4.5733333 | H27: Passe | N27: Safo Dan Ali | O27: Chaâwanatou | P27: Ichaou | Q27: F | R27: 40909 | S27: Safo Dan Ali | T27: Passant | U27: 5.88 | V27: 5.47 | W27: non Admise | X27: Redouble
N28: Safo Dan Ali | O28: Harissa | P28: Moussa | Q28: F | R28: 40909 | S28: Safo Dan Ali | T28: Passant | U28: 8.02 | V28: 3.69 | W28: non Admise | X28: Redouble
A29: MARADOU Centre | B29: Najiba Haladou | C29: F | D29: 5.96 | E29: 5.46 | F29: 5.5 | G29: 5.64 | H29: Passe | N29: Safo Dan Ali | O29: Lamratou | P29: Saidou | Q29: F | R29: 40909 | S29: Safo Dan Ali | T29: Passant | U29: 8.29 | V29: 6.51 | W29: 6.55 | X29: CEG
A30: MARADOU Centre | B30: Saadiya Moussa | C30: F | D30: 6 | E30: 6.5 | F30: 5.26 | G30: 5.92 | H30: Passe | N30: Safo Dan Ali | O30: Mariama | P30: Laouali | Q30: F | R30: 40909 | S30: Safo Dan Ali | T30: Passant | U30: 6.44 | V30: 5.02 | W30: non Admise | X30: Redouble
A31: MARADOU Centre | B31: Khadidja Hadi | C31: F | D31: 4 | E31: 5.5 | F31: 5.24 | G31: 4.58 | H31: Passe | N31: Safo Dan Ali | O31: Mariama | P31: Salissou | Q31: F | R31: 40909 | S31: Safo Dan Ali | T31: Passant | U31: 5.52 | V31: 3.5 | W31: non Admise | X31: Redouble
A32: MARADOU Centre | B32: Firdaoussi Tassiou | C32: F | D32: 3.32 | E32: 4.93 | F32: 5.52 | G32: 4.59 | H32: Passe | N32: Safo Dan Ali | O32: Mounawara | P32: Larwanou | Q32: F | R32: 40909 | S32: Safo Dan Ali | T32: Passant | U32: 9.38 | V32: 8.29 | W32: 8.5 | X32: CEG
A33: MARADOU Centre | B33: Yassimina Illa | C33: F | D33: 3.67 | E33: 4.98 | F33: 6 | G33: 4.7 | H33: Passe | N33: Safo Dan Ali | O33: Mouhoussina | P33: Rabé | Q33: F | R33: 40909 | S33: Safo Dan Ali | T33: Passant | U33: 5.7 | V33: 2.41 | W33: non Admise | X33: Redouble
A34: MARADOU Centre | B34: Khadidja Maty | C34: F | D34: 3.68 | E34: 4.66 | F34: 5.54 | G34: 4.62 | H34: Passe | N34: Safo Dan Ali | O34: Rahila | P34: Saidou | Q34: F | R34: 40909 | S34: Safo Dan Ali | T34: Passant | U34: 6.05 | V34: 5.7 | W34: non Admise | X34: Redouble
A35: MARADOU Centre | B35: Firdaoussi Laouali | C35: F | D35: 0 | E35: 0 | F35: 3 | G35: 1 | H35: rédble le CM1 | N35: Safo Dan Ali | O35: Sadika | P35: Ousmane | Q35: F | R35: 40909 | S35: Safo Dan Ali | T35: Passant | U35: 7.52 | V35: 5.79 | W35: 5 | X35: CEG
A36: MARADOU Centre | B36: Habsatou Nouhou | C36: F | D36: 0 | E36: 3 | F36: 0 | G36: 1 | H36: rédble le CM1 | N36: Safo Dan Ali | O36: Zeinabou | P36: Issa | Q36: F | R36: 40909 | S36: Safo Dan Ali | T36: Passant | U36: 6.47 | V36: 5.67 | W36: 4.85 | X36: CEG
A37: MARADOU Centre | B37: Mounawara Salélé | C37: F | D37: 0 | E37: 3 | F37: 0 | G37: 1 | H37: rédble le CM1 | N37: Safo Dan Ali | O37: Nana Firdaoussi | P37: M Yaou | Q37: F | R37: 40544 | S37: Safo Dan Ali | T37: Redoublant | U37: 6.47 | V37: 5.79 | W37: non Admise | X37: Orienté CFM
A38: MARADOU Centre | B38: Aicha Nafiou | C38: F | D38: 6.4 | E38: 6 | F38: 6.2 | G38: 6.2 | H38: Passe | O38: ECOLE TCHIKADJI CENTRE
A39: MARADOU Centre | B39: Anifa Ibrahim | C39: F | D39: 3.76 | E39: 4.5 | F39: 5.7 | G39: =(F39+E39+D39)/3 -> 4.6533333 | H39: Passe | N39: Tchikadji Centre | O39: Ouma Maimounatou | Q39: F | R39: 40909 | S39: Tchikadji | T39: Passant | U39: 5.95 | V39: 3.41 | W39: non Admise | X39: Orienté CFM
A40: MARADOU Centre | B40: Chamsiya Yahaya | C40: F | D40: 3.87 | E40: 4.78 | F40: 5.5 | G40: =(F40+E40+D40)/3 -> 4.7166667 | H40: Passe | N40: Tchikadji Centre | O40: Amira | P40: Abdou | Q40: F | R40: 40909 | S40: Tchikadji | T40: Passant | U40: 8.17 | V40: 5.2 | W40: non Admise | X40: Redouble
A41: MARADOU Centre | B41: Hassana Rabé | C41: F | D41: 5 | E41: 5 | F41: 4.94 | G41: =(F41+E41+D41)/3 -> 4.98 | H41: Passe | N41: Tchikadji Centre | O41: Balkissa | P41: Laouali | Q41: F | R41: 40909 | S41: Tchikadji | T41: Passant | U41: 8.42 | V41: 6.91 | W41: 7.45 | X41: CEG
A42: MARADOU Centre | B42: Kadidja Soupianou | C42: F | D42: 4 | E42: 5.65 | F42: 4 | G42: =(F42+E42+D42)/3 -> 4.55 | H42: Passe | N42: Tchikadji Centre | O42: Fatchima | P42: Garba | Q42: F | R42: 40909 | S42: Tchikadji | T42: Passant | U42: 8.55 | V42: 6.94 | W42: 6.25 | X42: CEG
A43: MARADOU Centre | B43: Koursiya Laouali | C43: F | D43: 3.5 | E43: 4.76 | F43: 5.9 | G43: =(F43+E43+D43)/3 -> 4.72 | H43: Passe | N43: Tchikadji Centre | O43: Habsatou | P43: Moussa | Q43: F | R43: 40909 | S43: Tchikadji | T43: Passant | U43: 7.52 | V43: 6.14 | W43: non Admise | X43: Redouble
...

Sheet CM1
A1: Ecole | B1: PRENOMS ET NOMS | C1: Sexe | D1: 1ere Evaluation | E1: 2ème Evaluation | F1: 3ème COMPO | G1: Moyenne Annuelle | H1: Situation Finale
A2: Safo Nassaraoua | B2: Faouziya Harouna | C2: F | D2: 8.44 | E2: 8.73 | F2: 8.62 | G2: =(D2+E2+F2)/3 -> 8.5966667 | H2: Passe
A3: Safo Nassaraoua | B3: Chamsiya Chitou | C3: F | D3: 6.63 | E3: 5.78 | F3: 5.22 | G3: =(D3+E3+F3)/3 -> 5.8766667 | H3: Passe
A4: Safo Nassaraoua | B4: Hanifa Amadou | C4: F | D4: 8.27 | E4: 7.98 | F4: 8.13 | G4: =(D4+E4+F4)/3 -> 8.1266667 | H4: Passe
A5: Safo Nassaraoua | B5: Rafia Tanimoune | C5: F | D5: 7.41 | E5: 6.83 | F5: 6.66 | G5: =(D5+E5+F5)/3 -> 6.9666667 | H5: Passe
A6: Safo Nassaraoua | B6: Fatima Salissou | C6: F | D6: 4.69 | E6: 4.25 | F6: 5.14 | G6: =(D6+E6+F6)/3 -> 4.6933333 | H6: Passe
A7: Safo Nassaraoua | B7: Zeinab Harouna | C7: F | D7: 5.21 | E7: 4.66 | F7: 3.94 | G7: =(D7+E7+F7)/3 -> 4.6033333 | H7: Passe
A8: Safo Nassaraoua | B8: Manira Laouali | C8: F | D8: 6.01 | E8: 5.24 | F8: 3.55 | G8: =(D8+E8+F8)/3 -> 4.9333333 | H8: Passe
A9: Safo Nassaraoua | B9: Aziza Nouhou | C9: F | D9: 4.78 | E9: 4.23 | F9: 5.18 | G9: =(D9+E9+F9)/3 -> 4.73 | H9: Passe
A10: Safo Nassaraoua | B10: Mouhoussina Dayabou | C10: F | D10: 5.21 | E10: 4.39 | F10: 3.96 | G10: =(D10+E10+F10)/3 -> 4.52 | H10: Passe
A11: Safo Nassaraoua | B11: Oumma abiha Saminou | C11: F | D11: 8.22 | E11: 7.54 | F11: 7.41 | G11: =(D11+E11+F11)/3 -> 7.7233333 | H11: Passe
A12: Safo Nassaraoua | B12: Oumaeira Kabirou | C12: F | D12: 5.62 | E12: 5.17 | F12: 4.44 | G12: =(D12+E12+F12)/3 -> 5.0766667 | H12: Passe
A13: Safo Nassaraoua | B13: Souraya Illa | C13: F | D13: 4.24 | E13: 4.99 | F13: 4.95 | G13: =(D13+E13+F13)/3 -> 4.7266667 | H13: Passe
... A16: Safo Nassaraoua | B16: Roufaatou Abdousalam | C16: F | D16: 3.96 | E16: 4.85 | F16: 4.91 | G16: =(D16+E16+F16)/3 -> 4.5733333 | H16: Passe
A17: MARADOU Centre | B17: Najiba Haladou | C17: F | D17: 5.96 | E17: 5.46 | F17: 5.5 | G17: 5.64 | H17: Passe
A18: MARADOU Centre | B18: Saadiya Moussa | C18: F | D18: 6 | E18: 6.5 | F18: 5.26 | G18: 5.92 | H18: Passe
A19: MARADOU Centre | B19: Khadidja Hadi | C19: F | D19: 4 | E19: 5.5 | F19: 5.24 | G19: 4.58 | H19: Passe
A20: MARADOU Centre | B20: Firdaoussi Tassiou | C20: F | D20: 3.32 | E20: 4.93 | F20: 5.52 | G20: 4.59 | H20: Passe
A21: MARADOU Centre | B21: Yassimina Illa | C21: F | D21: 3.67 | E21: 4.98 | F21: 6 | G21: 4.7 | H21: Passe
A22: MARADOU Centre | B22: Khadidja Maty | C22: F | D22: 3.68 | E22: 4.66 | F22: 5.54 | G22: 4.62 | H22: Passe
A23: MARADOU Centre | B23: Firdaoussi Laouali | C23: F | D23: 0 | E23: 0 | F23: 3 | G23: 1 | H23: rédble le CM1
A24: MARADOU Centre | B24: Habsatou Nouhou | C24: F | D24: 0 | E24: 3 | F24: 0 | G24: 1 | H24: rédble le CM1
A25: MARADOU Centre | B25: Mounawara Salélé | C25: F | D25: 0 | E25: 3 | F25: 0 | G25: 1 | H25: rédble le CM1
A26: MARADOU Centre | B26: Aicha Nafiou | C26: F | D26: 6.4 | E26: 6 | F26: 6.2 | G26: 6.2 | H26: Passe
A27: MARADOU Centre | B27: Anifa Ibrahim | C27: F | D27: 3.76 | E27: 4.5 | F27: 5.7 | G27: =(F27+E27+D27)/3 -> 4.6533333 | H27: Passe
A28: MARADOU Centre | B28: Chamsiya Yahaya | C28: F | D28: 3.87 | E28: 4.78 | F28: 5.5 | G28: =(F28+E28+D28)/3 -> 4.7166667 | H28: Passe
A29: MARADOU Centre | B29: Hassana Rabé | C29: F | D29: 5 | E29: 5 | F29: 4.94 | G29: =(F29+E29+D29)/3 -> 4.98 | H29: Passe
A30: MARADOU Centre | B30: Kadidja Soupianou | C30: F | D30: 4 | E30: 5.65 | F30: 4 | G30: =(F30+E30+D30)/3 -> 4.55 | H30: Passe
A31: MARADOU Centre | B31: Koursiya Laouali | C31: F | D31: 3.5 | E31: 4.76 | F31: 5.9 | G31: =(F31+E31+D31)/3 -> 4.72 | H31: Passe
A32: MARADOU Centre | B32: Malika Hamissou | C32: F | D32: 9.25 | E32: 8.7 | F32: 8 | G32: =(F32+E32+D32)/3 -> 8.65 | H32: Passe
A33: MARADOU Centre | B33: Malika Salissou | C33: F | D33: 8 | E33: 8.6 | F33: 8.27 | G33: =(F33+E33+D33)/3 -> 8.29 | H33: Passe
A34: MARADOU Centre | B34: Mariyama Laminou | C34: F | D34: 3.13 | E34: 4.6 | F34: 5.9 | G34: =(F34+E34+D34)/3 -> 4.5433333 | H34: Passe
A35: MARADOU Centre | B35: Maryam Laouali | C35: F | D35: 4.15 | E35: 4.98 | F35: 4.78 | G35: =(F35+E35+D35)/3 -> 4.6366667 | H35: Passe
A36: MARADOU Centre | B36: Nabila Yahaya | C36: F | D36: 6.21 | E36: 6 | F36: 6.6 | G36: =(F36+E36+D36)/3 -> 6.27 | H36: Passe
A37: MARADOU Centre | B37: Nazira Souley | C37: F | D37: 3.5 | E37: 4.5 | F37: 5.5 | G37: =(F37+E37+D37)/3 -> 4.5 | H37: Passe
A38: MARADOU Centre | B38: Rafi'a Rabiou | C38: F | D38: 8.24 | E38: 9 | F38: 9.4 | G38: =(F38+E38+D38)/3 -> 8.88 | H38: Passe
... A43: MARADOU Centre | B43: Zahariya Salissou | C43: F | D43: 3.55 | E43: 3.95 | F43: 6 | G43: =(F43+E43+D43)/3 -> 4.5 | H43: Passe
A44: MARADOU Centre | B44: Zainab Souley | C44: F | D44: 5 | E44: 5.15 | F44: 5.2 | G44: 5.25 | H44: Passe
A45: Total | B45: =SUBTOTAL(103,'CM1'!$B$2:$B$44) -> 43 | D45: =SUBTOTAL(101,'CM1'!$D$2:$D$44) -> 4.9004651 | E45: =SUBTOTAL(101,'CM1'!$E$2:$E$44) -> 5.3637209 | F45: =SUBTOTAL(101,'CM1'!$F$2:$F$44) -> 5.4574419 | G45: =SUBTOTAL(101,'CM1'!$G$2:$G$44) -> 5.2314729 | H45: =SUBTOTAL(103,'CM1'!$H$2:$H$44) -> 43

Sheet CM2
A1: Ecole | B1: Prénom | C1: Nom de famille | D1: Sexe | E1: Date de naissance | F1: Lieu de naissance | G1: Statut | H1: 1er trim | I1: 2eme trim | J1: moy CFEPD | K1: Situations FINALES | L1: Comments
A2: Safo Nassaraoua | B2: Amira | C2: Ali | D2: F | E2: 40874 | F2: Safo NASSARAOUA | G2: Passant | H2: 5.2 | I2: 6.11 | J2: non Admise | K2: Redouble
A3: Safo Nassaraoua | B3: Balkissa | C3: Daouda | D3: F | E3: 40909 | F3: Safo NASSARAOUA | G3: Passant | H3: 4.3 | I3: 5.29 | J3: non Admise | K3: Redouble
A4: Safo Nassaraoua | B4: Hassia | C4: Ali | D4: F | E4: 40909 | F4: Safo NASSARAOUA | G4: Passant | H4: 5.29 | I4: 6.14 | J4: non Admise | K4: Redouble
A5: Safo Nassaraoua | B5: Laouratou | C5: Minnirou | D5: F | E5: 40775 | F5: Safo NASSARAOUA | G5: Passant | H5: 7.38 | I5: 8 | J5: 5.21 | K5: CEG
A6: Safo Nassaraoua | B6: Mouhoussina | C6: Issoufou | D6: F | E6: 40909 | F6: Safo NASSARAOUA | G6: Passant | H6: 4.57 | I6: 0 | J6: non Admise | K6: Redouble
A7: Safo Nassaraoua | B7: Nana Moustahida | C7: Idi | D7: F | E7: 41396 | F7: Safo NASSARAOUA | G7: Passant | H7: 6.29 | I7: 7.91 | J7: 6.36 | K7: CEG
A8: Safo Nassaraoua | B8: Nana Bassira | C8: Chitou | D8: F | E8: 40909 | F8: Safo NASSARAOUA | G8: Passant | H8: 5.04 | I8: 5.52 | J8: non Admise | K8: Redouble
A9: Safo Nassaraoua | B9: Nana Kaoussar | C9: Tassiou | D9: F | E9: 41368 | F9: Safo NASSARAOUA | G9: Passant | H9: 6.89 | I9: 8.67 | J9: 7.18 | K9: CEG
A10: Safo Nassaraoua | B10: Samira | C10: Abdoulaye | D10: F | E10: 40909 | F10: Safo NASSARAOUA | G10: Passant | H10: 6.01 | I10: 5.52 | J10: 6.02 | K10: CEG
A11: Safo Nassaraoua | B11: Soumaya | C11: Youchaou | D11: F | E11: 40659 | F11: Safo NASSARAOUA | G11: Passant | H11: 5.1 | I11: 5.26 | J11: non Admise | K11: Redouble
A12: Safo Nassaraoua | B12: Zaharaou | C12: Souley | D12: F | E12: 40179 | F12: Safo NASSARAOUA | G12: Redoublant | H12: 4.35 | I12: 4.2 | J12: 4.65 | K12: CEG
A13: Safo Nassaraoua | B13: Farida | C13: Mahamane | D13: F | E13: 40673 | F13: Safo NASSARAOUA | G13: Redoublant | H13: 4.66 | I13: 4.02 | J13: 4.5 | K13: CEG
A14: Safo Dan Ali | B14: Aicha | C14: Issaka | D14: F | E14: 40909 | F14: Safo Dan Ali | G14: Passant | H14: 6.64 | I14: 5.8 | J14: 4.56 | K14: CEG
A15: Safo Dan Ali | B15: Chaâwanatou | C15: Ichaou | D15: F | E15: 40909 | F15: Safo Dan Ali | G15: Passant | H15: 5.88 | I15: 5.47 | J15: non Admise | K15: Redouble
A16: Safo Dan Ali | B16: Harissa | C16: Moussa | D16: F | E16: 40909 | F16: Safo Dan Ali | G16: Passant | H16: 8.02 | I16: 3.69 | J16: non Admise | K16: Redouble
A17: Safo Dan Ali | B17: Lamratou | C17: Saidou | D17: F | E17: 40909 | F17: Safo Dan Ali | G17: Passant | H17: 8.29 | I17: 6.51 | J17: 6.55 | K17: CEG
A18: Safo Dan Ali | B18: Mariama | C18: Laouali | D18: F | E18: 40909 | F18: Safo Dan Ali | G18: Passant | H18: 6.44 | I18: 5.02 | J18: non Admise | K18: Redouble
A19: Safo Dan Ali | B19: Mariama | C19: Salissou | D19: F | E19: 40909 | F19: Safo Dan Ali | G19: Passant | H19: 5.52 | I19: 3.5 | J19: non Admise | K19: Redouble
A20: Safo Dan Ali | B20: Mounawara | C20: Larwanou | D20: F | E20: 40909 | F20: Safo Dan Ali | G20: Passant | H20: 9.38 | I20: 8.29 | J20: 8.5 | K20: CEG
A21: Safo Dan Ali | B21: Mouhoussina | C21: Rabé | D21: F | E21: 40909 | F21: Safo Dan Ali | G21: Passant | H21: 5.7 | I21: 2.41 | J21: non Admise | K21: Redouble
A22: Safo Dan Ali | B22: Rahila | C22: Saidou | D22: F | E22: 40909 | F22: Safo Dan Ali | G22: Passant | H22: 6.05 | I22: 5.7 | J22: non Admise | K22: Redouble
A23: Safo Dan Ali | B23: Sadika | C23: Ousmane | D23: F | E23: 40909 | F23: Safo Dan Ali | G23: Passant | H23: 7.52 | I23: 5.79 | J23: 5 | K23: CEG
A24: Safo Dan Ali | B24: Zeinabou | C24: Issa | D24: F | E24: 40909 | F24: Safo Dan Ali | G24: Passant | H24: 6.47 | I24: 5.67 | J24: 4.85 | K24: CEG
A25: Safo Dan Ali | B25: Nana Firdaoussi | C25: M Yaou | D25: F | E25: 40544 | F25: Safo Dan Ali | G25: Redoublant | H25: 6.47 | I25: 5.79 | J25: non Admise | K25: Orienté CFM
A26: Tchikadji Centre | B26: Ouma | C26: Maimounatou | D26: F | E26: 40909 | F26: Tchikadji | G26: Passant | H26: 5.95 | I26: 3.41 | J26: non Admise | K26: Orienté CFM
A27: Tchikadji Centre | B27: Amira | C27: Abdou | D27: F | E27: 40909 | F27: Tchikadji | G27: Passant | H27: 8.17 | I27: 5.2 | J27: non Admise | K27: Redouble
A28: Tchikadji Centre | B28: Balkissa | C28: Laouali | D28: F | E28: 40909 | F28: Tchikadji | G28: Passant | H28: 8.42 | I28: 6.91 | J28: 7.45 | K28: CEG
A29: Tchikadji Centre | B29: Fatchima | C29: Garba | D29: F | E29: 40909 | F29: Tchikadji | G29: Passant | H29: 8.55 | I29: 6.94 | J29: 6.25 | K29: CEG
A30: Tchikadji Centre | B30: Habsatou | C30: Moussa | D30: F | E30: 40909 | F30: Tchikadji | G30: Passant | H30: 7.52 | I30: 6.14 | J30: non Admise | K30: Redouble
A31: Tchikadji Centre | B31: Ikilima | C31: Abdou | D31: F | E31: 40909 | F31: Tchikadji | G31: Passant | H31: 7.76 | I31: 5.85 | J31: non Admise | K31: Redouble
A32: Tchikadji Centre | B32: Khadidja | C32: Hassan | D32: F | E32: 40909 | F32: Tchikadji | G32: Passant | H32: 6.97 | I32: 5.17 | J32: non Admise | K32: Redouble
A33: Tchikadji Centre | B33: Mariam | C33: Laouali | D33: F | E33: 40909 | F33: Tchikadji | G33: Passant | H33: 7.42 | I33: 5.35 | J33: non Admise | K33: Redouble
A34: Tchikadji Centre | B34: Rakia | C34: Achirou | D34: F | E34: 40909 | F34: Tchikadji | G34: Passant | H34: 6.69 | I34: 5.14 | J34: non Admise | K34: Redouble
A35: Tchikadji Centre | B35: Zeinab | C35: Aboubacar | D35: F | E35: 40909 | F35: Tchikadji | G35: Passant | H35: 6.35 | I35: 7.41 | J35: 5.25 | K35: CEG
A36: Tchikadji Centre | B36: Mariam | C36: Abdou | D36: F | E36: 40544 | F36: Tchikadji | G36: Redoublant | H36: 6.58 | I36: 8.88 | J36: 5.65 | K36: CEG
A37: Tchikadji Centre | B37: Zeinab | C37: Sabiou | D37: F | E37: 40544 | F37: Tchikadji | G37: Redoublant | H37: 5.23 | I37: 5.29 | J37: 5 | K37: CEG
A38: Maradou Centre | B38: Alhéri | C38: Nouhou | D38: F | E38: 01/01/2012 | F38: Maradou | G38: Passant | H38: 7.25 | I38: 6.52 | J38: 5.63 | K38: CEG
A39: Maradou Centre | B39: Aichatou | C39: Sani | D39: F | E39: 01/01/2012 | F39: Maradou | G39: Passant | H39: 5.91 | I39: 4.6 | J39: non Admise | K39: Redouble
A40: Maradou Centre | B40: Amira | C40: Hamissou | D40: F | E40: 01/01/2012 | F40: Maradou | G40: Passant | H40: 4.52 | I40: 5.35 | J40: non Admise | K40: Redouble
...

Sheet CM1 & CM2 Metrics
E3: CM1
A4: Ecole | B4: Insrites | C4: Abandonee # | D4: Presentes | E4: Admises # | F4: Non Admise # | G4: Abandonee % | H4: Admises % | I4: Non Admise % | J4: Comments
A5: Maradou Centre | B5: 28 | C5: 0 | D5: 28 | E5: 25 | F5: 3 | G5: 0 | H5: ='CM1 & CM2 Metrics'!$E5/'CM1 & CM2 Metrics'!$D5 -> 0.89285714 | I5: ='CM1 & CM2 Metrics'!$F5/'CM1 & CM2 Metrics'!$D5 -> 0.10714286
A6: Safo Nassaraoua | B6: 15 | C6: 0 | D6: 15 | E6: 15 | F6: 0 | G6: 0 | H6: ='CM1 & CM2 Metrics'!$E6/'CM1 & CM2 Metrics'!$D6 -> 1 | I6: ='CM1 & CM2 Metrics'!$F6/'CM1 & CM2 Metrics'!$D6 -> 0
A7: Total | B7: =SUBTOTAL(109,'CM1 & CM2 Metrics'!$B$5:$B$6) -> 43 | D7: =SUBTOTAL(109,'CM1 & CM2 Metrics'!$D$5:$D$6) -> 43 | E7: =SUBTOTAL(109,'CM1 & CM2 Metrics'!$E$5:$E$6) -> 40 | F7: =SUBTOTAL(109,'CM1 & CM2 Metrics'!$F$5:$F$6) -> 3 | H7: ='CM1 & CM2 Metrics'!$E$7/'CM1 & CM2 Metrics'!$D$7 -> 0.93023256 | I7: ='CM1 & CM2 Metrics'!$F$7/'CM1 & CM2 Metrics'!$D$7 -> 0.069767442
E14: CM2
A15: Ecole | B15: Insrites | C15: Abandonee # | D15: Presentes | E15: Admises # | F15: Non Admise # | G15: Abandonee % | H15: Admises % | I15: Non Admise % | J15: Comments
A16: Maradou Centre | B16: 28 | C16: 0 | D16: 28 | E16: 12 | F16: 16 | G16: 0 | H16: ='CM1 & CM2 Metrics'!$E16/'CM1 & CM2 Metrics'!$D16 -> 0.42857143 | I16: ='CM1 & CM2 Metrics'!$F16/'CM1 & CM2 Metrics'!$D16 -> 0.57142857
A17: Safo Dan Ali | B17: 12 | C17: 0 | D17: 12 | E17: 5 | F17: 7 | G17: 0 | H17: ='CM1 & CM2 Metrics'!$E17/'CM1 & CM2 Metrics'!$D17 -> 0.41666667 | I17: ='CM1 & CM2 Metrics'!$F17/'CM1 & CM2 Metrics'!$D17 -> 0.58333333
A18: Safo Nassaraoua | B18: 12 | C18: 0 | D18: 12 | E18: 6 | F18: 6 | G18: 0 | H18: ='CM1 & CM2 Metrics'!$E18/'CM1 & CM2 Metrics'!$D18 -> 0.5 | I18: ='CM1 & CM2 Metrics'!$F18/'CM1 & CM2 Metrics'!$D18 -> 0.5
A19: Tchikadji Centre | B19: 12 | C19: 0 | D19: 12 | E19: 5 | F19: 7 | G19: 0 | H19: ='CM1 & CM2 Metrics'!$E19/'CM1 & CM2 Metrics'!$D19 -> 0.41666667 | I19: ='CM1 & CM2 Metrics'!$F19/'CM1 & CM2 Metrics'!$D19 -> 0.58333333
A20: Total | B20: =SUBTOTAL(109,'CM1 & CM2 Metrics'!$B$16:$B$19) -> 64 | C20: =SUBTOTAL(109,'CM1 & CM2 Metrics'!$C$16:$C$19) -> 0 | D20: =SUBTOTAL(109,'CM1 & CM2 Metrics'!$D$16:$D$19) -> 64 | E20: =SUBTOTAL(109,'CM1 & CM2 Metrics'!$E$16:$E$19) -> 28 | F20: =SUBTOTAL(109,'CM1 & CM2 Metrics'!$F$16:$F$19) -> 36 | H20: ='CM1 & CM2 Metrics'!$E$20/'CM1 & CM2 Metrics'!$D$20 -> 0.4375 | I20: ='CM1 & CM2 Metrics'!$F$20/'CM1 & CM2 Metrics'!$D$20 -> 0.5625
